Workbook
Name ActLab: #REF!
Name ActLab0: #REF!
Name ActMap: #REF!
Name actProd: #REF!
Name AEEI: #REF!
Name BridgeFileName: #REF!
Name CommAgg: #REF!
Name CommElas: #REF!
Name CommLab: #REF!
Name CommLab0: #REF!
Name CommMap: #REF!
Name depr: #REF!
Name Description: #REF!
Name Dyntab: #REF!
Name EMICO2: #REF!
Name escale: #REF!
Name EXR: #REF!
Name fdComm: #REF!
Name fdCommMap: #REF!
Name GDDebt0: #REF!
Name GDPMod: #REF!
Name GDPScen: #REF!
Name GFDebt0: #REF!
Name hhElas: defPar!$B$12:$C$35
Name ifEnglish: #REF!
Name inscale: #REF!
Name KSAMA0: #REF!
Name Labvol: #REF!
Name Lang: #REF!
Name miscElas: defPar!#REF!
Name NRGPrice: #REF!
Name PFDebt0: #REF!
Name Pop: #REF!
Name popScen: #REF!
Name prodElas: #REF!
Name pscale: #REF!
Name RGDDebt0: #REF!
Name RGFDebt0: #REF!
Name RoR0: #REF!
Name RPFDebt0: #REF!
Name SAM0: #REF!
Name SAMFileName: #REF!
Name SAMLab: #REF!
Name SamLab0: #REF!
Name samMap: #REF!
Name SAMVAL: #REF!
Name scenFileName: #REF!
Name timeScen: #REF!
Name wDir: #REF!

Sheet Dictionary
A1: Activities | D1: Commodities | H1: Factors | K1: Households | N1: Institutions | Q1: Taxes
A2: a-crp | B2: Crop Production | D2: c-crp | E2: Crop Production | H2: f-Land | I2: Land | K2: h-Dec1 | L2: Quintile 1 (poorest) | N2: e-ent | O2: Enterprises | Q2: t-Land | R2: =+I2&" factor tax" -> Land factor tax | T2: 1 | U2: pdr | V2: Paddy rice
A3: a-lvs | B3: Livestock production | D3: c-lvs | E3: Livestock production | H3: f-FrSkl | I3: Skilled formal Labor | K3: h-Dec2 | L3: Quintile 2 | N3: g-govt | O3: Government | Q3: t-labSk | R3: =+I3&" factor tax" -> Skilled formal Labor factor tax | T3: 2 | U3: wht | V3: Wheat
A4: a-frs | B4: Forestry | D4: c-frs | E4: Forestry | H4: f-FrNsk | I4: Unskilled formal Labor | K4: h-Dec3 | L4: Quintile 3 | N4: w-ww_world | O4: Rest of the World | Q4: t-labUs | R4: =+I4&" factor tax" -> Unskilled formal Labor factor tax | T4: 3 | U4: gro | V4: Cereal grains nec
A5: a-coa | B5: Coal | D5: c-coa | E5: Coal | H5: f-InNsk | I5: Unskilled Formal Labor | K5: h-Dec4 | L5: Quintile 4 | Q5: t-Capital | R5: =+I6&" factor tax" -> Capital factor tax | T5: 4 | U5: v_f | V5: Vegetables, fruit, nuts
A6: a-oil | B6: Oil | D6: c-oil | E6: Oil | H6: f-Capital | I6: Capital | K6: h-Dec5 | L6: Quintile 5 | Q6: t-NatlRes | R6: =+I7&" factor tax" -> Natural Resources factor tax | T6: 5 | U6: osd | V6: Oil seeds
A7: a-gas | B7: Gas | D7: c-gas | E7: Gas | H7: f-NatlRes | I7: Natural Resources | K7: h-Dec6 | L7: Quintile 6 | Q7: t-tmm_world | R7: Tariffs | T7: 6 | U7: c_b | V7: Sugar cane, sugar beet
A8: a-oxt | B8: Other Extraction | D8: c-oxt | E8: Other Extraction | K8: h-Dec7 | L8: Quintile 7 | Q8: t-PRODTAX | R8: Production tax | T8: 7 | U8: pfb | V8: Plant-based fibers
A9: a-fod | B9: Food products | D9: c-fod | E9: Food products | K9: h-Dec8 | L9: Quintile 8 | Q9: t-DIRTAX | R9: Diret tax | T9: 8 | U9: ocr | V9: Crops nec
A10: a-b_t | B10: Beverages and tobacco products | D10: c-b_t | E10: Beverages and tobacco products | K10: h-Dec9 | L10: Quintile 9 | Q10: t-tss | R10: Excise tax | T10: 9 | U10: ctl | V10: Bovine cattle, sheep and goats, horses
A11: a-tex | B11: Textiles | D11: c-tex | E11: Textiles | K11: h-DecX | L11: Quintile 10 (richest) | Q11: t-vat | R11: Value added tax | T11: 10 | U11: oap | V11: Animal products nec
A12: a-wod | B12: Wood products and paper | D12: c-wod | E12: Wood products and paper | T12: 11 | U12: rmk | V12: Raw milk
A13: a-p_c | B13: Petroleum, coal products | D13: c-p_c | E13: Petroleum, coal products | T13: 12 | U13: wol | V13: Wool, silk-worm cocoons
A14: a-chm | B14: Chemical products | D14: c-chm | E14: Chemical products | T14: 13 | U14: frs | V14: Forestry
A15: a-bph | B15: Basic pharmaceutical products | D15: c-bph | E15: Basic pharmaceutical products | T15: 14 | U15: fsh | V15: Fishing
A16: a-nmm | B16: Mineral products nec | D16: c-nmm | E16: Mineral products nec | T16: 15 | U16: coa
A17: a-i_s | B17: Ferrous metals | D17: c-i_s | E17: Ferrous metals | T17: 16 | U17: oil
A18: a-nfm | B18: Metals nec | D18: c-nfm | E18: Metals nec | T18: 17 | U18: gas
A19: a-fmp | B19: Metal products | D19: c-fmp | E19: Metal products | T19: 18 | U19: oxt
A20: a-ele | B20: Electrical equipment, electronics, machinery and equipment | D20: c-ele | E20: Electrical equipment, electronics, machinery and equipment | T20: 19 | U20: cmt
A21: a-mvh | B21: Motor vehicles and parts | D21: c-mvh | E21: Motor vehicles and parts | T21: 20 | U21: omt
A22: a-omf | B22: Manufactures nec | D22: c-omf | E22: Manufactures nec | T22: 21 | U22: vol
A23: a-TnD | B23: Electricity transmission and distribution | D23: c-TnD | E23: Electricity transmission and distribution | T23: 22 | U23: mil
A24: a-NuclearP | B24: Nuvlear Power | D24: c-ely | E24: Electricity | T24: 23 | U24: pcr
A25: a-CoalP | B25: Coal Power | D25: c-gdt | E25: Gas distribution | T25: 24 | U25: sgr
A26: a-GasP | B26: Gas Power | D26: c-wtr | E26: Water, waste and utilities | T26: 25 | U26: ofd
A27: a-WindP | B27: Wind Power | D27: c-cns | E27: Construction | T27: 26 | U27: b_t
... A40: a-ofi | B40: Financial services nec | D40: c-hht | E40: Human health and social work activities | T40: 39 | U40: fmp
A41: a-ins | B41: Insurance (formerly isr) | T41: 40 | U41: ele
A42: a-osr | B42: Business services nec | T42: 41 | U42: eeq
A43: a-osg | B43: Public Administration and defense | T43: 42 | U43: ome
A44: a-edu | B44: Education | T44: 43 | U44: mvh
A45: a-hht | B45: Human health and social work activities | T45: 44 | U45: otn
T46: 45 | U46: omf
T47: 46 | U47: ely
T48: 47 | U48: gdt
T49: 48 | U49: wtr
T50: 49 | U50: cns
T51: 50 | U51: trd
T52: 51 | U52: afs
...

Sheet Layout
A1: LAYOUT
A3: Comment | B3: Data Type | C3: Name | D3: Location | E3: Row dimension | F3: Column dimension | G3: Total dimension
E4: rdim | F4: cdim | G4: dim
A5: Maping from activities to GTAP | B5: set | C5: mapaGTAP | D5: =IF(B5="dset","Sets!"&HLOOKUP(C5,sets!$B$2:$WY$3,2,)&6,IF(B5="set","Maps!"&HLOOKUP(C5,maps!$A$2:$ZH$3,2,)&6)) -> Maps!A6 | E5: 2
A6: Maping from products to GTAP | B6: set | C6: mapcGTAP | D6: =IF(B6="dset","Sets!"&HLOOKUP(C6,sets!$B$2:$WY$3,2,)&6,IF(B6="set","Maps!"&HLOOKUP(C6,maps!$A$2:$ZH$3,2,)&6)) -> Maps!D6 | E6: 2
A7: All accounts (plus nests) | B7: dset | C7: is | D7: =IF(B7="dset","Sets!"&HLOOKUP(C7,sets!$B$2:$WY$3,2,)&6,IF(B7="set","Maps!"&HLOOKUP(C7,maps!$A$2:$ZH$3,2,)&6)) -> Sets!B6 | E7: 1
A8: Energy products | B8: dset | C8: e | D8: =IF(B8="dset","Sets!"&HLOOKUP(C8,sets!$B$2:$WY$3,2,)&6,IF(B8="set","Maps!"&HLOOKUP(C8,maps!$A$2:$ZH$3,2,)&6)) -> Sets!G6 | E8: 1
A9: Debt account | B9: dset | C9: debt | D9: =IF(B9="dset","Sets!"&HLOOKUP(C9,sets!$B$2:$WY$3,2,)&6,IF(B9="set","Maps!"&HLOOKUP(C9,maps!$A$2:$ZH$3,2,)&6)) -> Sets!S6 | E9: 1
A10: Labor accounts | B10: dset | C10: l | D10: =IF(B10="dset","Sets!"&HLOOKUP(C10,sets!$B$2:$WY$3,2,)&6,IF(B10="set","Maps!"&HLOOKUP(C10,maps!$A$2:$ZH$3,2,)&6)) -> Sets!H6 | E10: 1
A11: Capital account | B11: dset | C11: cap | D11: =IF(B11="dset","Sets!"&HLOOKUP(C11,sets!$B$2:$WY$3,2,)&6,IF(B11="set","Maps!"&HLOOKUP(C11,maps!$A$2:$ZH$3,2,)&6)) -> Sets!I6 | E11: 1
A12: Land accounts | B12: dset | C12: lnd | D12: =IF(B12="dset","Sets!"&HLOOKUP(C12,sets!$B$2:$WY$3,2,)&6,IF(B12="set","Maps!"&HLOOKUP(C12,maps!$A$2:$ZH$3,2,)&6)) -> Sets!J6 | E12: 1
A13: Natural ressources | B13: dset | C13: natres | D13: =IF(B13="dset","Sets!"&HLOOKUP(C13,sets!$B$2:$WY$3,2,)&6,IF(B13="set","Maps!"&HLOOKUP(C13,maps!$A$2:$ZH$3,2,)&6)) -> Sets!K6 | E13: 1
A14: All investment account | B14: dset | C14: inv | D14: =IF(B14="dset","Sets!"&HLOOKUP(C14,sets!$B$2:$WY$3,2,)&6,IF(B14="set","Maps!"&HLOOKUP(C14,maps!$A$2:$ZH$3,2,)&6)) -> Sets!L6 | E14: 1
A15: Government investment account | B15: dset | C15: ginv | D15: =IF(B15="dset","Sets!"&HLOOKUP(C15,sets!$B$2:$WY$3,2,)&6,IF(B15="set","Maps!"&HLOOKUP(C15,maps!$A$2:$ZH$3,2,)&6)) -> Sets!M6 | E15: 1
A16: Adaptive investment account | B16: dset | C16: adpinv | D16: =IF(B16="dset","Sets!"&HLOOKUP(C16,sets!$B$2:$WY$3,2,)&6,IF(B16="set","Maps!"&HLOOKUP(C16,maps!$A$2:$ZH$3,2,)&6)) -> Sets!N6 | E16: 1
... A21: Aggregation from proto to final SAM | B21: set | C21: mapis | D21: =IF(B21="dset","Sets!"&HLOOKUP(C21,sets!$B$2:$WY$3,2,)&6,IF(B21="set","Maps!"&HLOOKUP(C21,maps!$A$2:$ZH$3,2,)&6)) -> Maps!G6 | E21: 2
A22: Demand bundle composition | B22: par | C22: mapkNestShr | D22: mapk!B5 | E22: 1 | F22: 1
A23: Substitutional elasticities in demand nests | B23: par | C23: sigmacNest0 | D23: mapk!C2 | F23: 1
A24: Map from aggregated to single sectors | B24: set | C24: mapaagr | D24: =IF(B24="dset","Sets!"&HLOOKUP(C24,sets!$B$2:$WY$3,2,)&6,IF(B24="set","Maps!"&HLOOKUP(C24,maps!$A$2:$ZH$3,2,)&6)) -> Maps!M6 | E24: 2
A25: Production nesting | B25: par | C25: pnest | D25: pnest!B6 | E25: 2 | F25: 1
A26: Substitution elasticities for production nests | B26: par | C26: subselas | D26: pnest!C2 | E26: 1 | F26: 1
A27: Factor market nestings | B27: par | C27: fmNest | D27: fmNest!B9
A28: Parameters for factor market nests | B28: par | C28: fmNestPar | D28: fmNest!B2
A29: GTAPVersion | B29: dset | C29: GTAPVersion | D29: =IF(B29="dset","Sets!"&HLOOKUP(C29,sets!$B$2:$WY$3,2,)&6,IF(B29="set","Maps!"&HLOOKUP(C29,maps!$A$2:$ZH$3,2,)&6)) -> Sets!U6 | E29: 1
A30: BaseYear | B30: dset | C30: BaseYear | D30: =IF(B30="dset","Sets!"&HLOOKUP(C30,sets!$B$2:$WY$3,2,)&6,IF(B30="set","Maps!"&HLOOKUP(C30,maps!$A$2:$ZH$3,2,)&6)) -> Sets!V6 | E30: 1
A31: Age cohotrs | B31: dset | C31: cohorts | D31: =IF(B31="dset","Sets!"&HLOOKUP(C31,sets!$B$2:$WY$3,2,)&6,IF(B31="set","Maps!"&HLOOKUP(C31,maps!$A$2:$ZH$3,2,)&6)) -> Sets!Q6 | E31: 1
A32: Initial SAM | B32: par | C32: SAM0 | D32: SAM!A1 | E32: 1 | F32: 1
A33: default parameter values | B33: par | C33: defPar | D33: defPar!B2 | E33: 1
A34: exceptions in activity parameters | B34: par | C34: actPar | D34: actPar!A1 | E34: 1 | F34: 2
A35: exceptions in commodity parameters | B35: par | C35: comPar | D35: comPar!A1 | E35: 1 | F35: 1
A36: exceptions in HH parameters | B36: par | C36: hohPar | D36: hohPar!B9 | E36: 1 | F36: 2
A37: exceptions inother parameters | B37: par | C37: othpar | D37: othPar!A1 | E37: 1 | F37: 1
A38: labor quantities for initial SAM, aggregated to model SAM dimensions in base.inc | B38: par | C38: labor0 | D38: labor!B1 | E38: 1 | F38: 1
A39: Official Emission inventory - combustion | B39: par | C39: emiInventory_OFF | D39: emiinv!A2 | E39: 1 | F39: 1
A40: Power mix | B40: par | C40: powerMix | D40: powerMix!A1 | E40: 2 | F40: 1
A41: GHG mitigation | B41: par | C41: GHGMitigation | D41: GHGMitigation!A1 | E41: 2 | F41: 1
A42: Energy projections | B42: par | C42: energyProj | D42: Energy!A1 | E42: 3 | F42: 1
A43: Nutrient contents | B43: par | C43: nutCont | D43: Nutrients!A1 | E43: 1 | F43: 1
A44: Points on Marginal Abatement Cost Curves | B44: par | C44: macc | D44: macc!A1 | E44: 1 | F44: 1
A45: Regression parameter to render CDE income dependent | B45: par | C45: regparIncomeCDE | D45: hohPar!A3 | E45: 2 | F45: 1
...

Sheet MACC
B1: 0 | C1: 1 | D1: 5 | E1: 10 | F1: 50 | G1: 100 | H1: 360 | I1: 380
A2: rest | B2: 1e-10 | C2: 1e-06 | D2: 0.05 | E2: 0.1 | F2: 0.2 | G2: 0.5 | H2: 0.6 | I2: 1
A3: a-nmm | B3: 1e-10 | C3: 1e-06 | D3: 0.0001 | F3: 0.9 | G3: 0.95 | H3: 0.99 | I3: 1
A4: a-crp | B4: 1e-10 | C4: 1e-06 | D4: 0.0001 | F4: 0.75 | G4: 0.9 | H4: 0.95 | I4: 1
A5: a-ele | B5: 1e-10 | C5: 1e-06 | D5: 0.0001 | F5: 0.2 | G5: 0.3 | H5: 0.4 | I5: 1
A6: a-wtr | B6: 1e-10 | C6: 1e-06 | D6: 0.0001 | F6: 0.2 | G6: 0.3 | H6: 0.4 | I6: 1
A7: a-oap | B7: 1e-10 | C7: 1e-06 | D7: 0.0001 | G7: 0.07 | H7: 0.08 | I7: 1
A8: a-wol | B8: 1e-10 | C8: 1e-06 | D8: 0.0001 | G8: 0.07 | H8: 0.08 | I8: 1
A9: a-ctl | B9: 1e-10 | C9: 1e-06 | D9: 0.0001 | G9: 0.07 | H9: 0.08 | I9: 1
A10: a-ctlRais | B10: 1e-10 | C10: 1e-06 | D10: 0.0001 | G10: 0.07 | H10: 0.08 | I10: 1
A11: a-rmk | B11: 1e-10 | C11: 1e-06 | D11: 0.0001 | G11: 0.07 | H11: 0.08 | I11: 1
A12: a-pdr | B12: 1e-10 | C12: 1e-06 | D12: 0.0001 | G12: 0.16 | H12: 0.17 | I12: 1
A13: a-wht | B13: 1e-10 | C13: 1e-06 | D13: 0.0001 | G13: 0.1 | H13: 0.12 | I13: 1
A14: a-gro | B14: 1e-10 | C14: 1e-06 | D14: 0.0001 | G14: 0.1 | H14: 0.12 | I14: 1
A15: a-osd | B15: 1e-10 | C15: 1e-06 | D15: 0.0001 | G15: 0.1 | H15: 0.12 | I15: 1
A16: a-v_f | B16: 1e-10 | C16: 1e-06 | D16: 0.0001 | G16: 0.1 | H16: 0.12 | I16: 1
A17: a-pbf | B17: 1e-10 | C17: 1e-06 | D17: 0.0001 | G17: 0.1 | H17: 0.12 | I17: 1
A18: a-c_b | B18: 1e-10 | C18: 1e-06 | D18: 0.0001 | G18: 0.1 | H18: 0.12 | I18: 1
A19: a-ocr | B19: 1e-10 | C19: 1e-06 | D19: 0.0001 | G19: 0.1 | H19: 0.12 | I19: 1

Sheet sets
B1: Model Specific Sets
B2: =+B5 -> is | C2: =+C5 -> 0 | D2: =+D5 -> aagr | G2: =+G5 -> e | H2: =+H5 -> l | I2: =+I5 -> cap | J2: =+J5 -> lnd | K2: =+K5 -> natres | L2: =+L5 -> inv | M2: =+M5 -> ginv | N2: =+N5 -> adpinv | ... Q2: =+Q5 -> cohorts | S2: =+S5 -> debt | T2: =+T5 -> nrgfac | U2: =+U5 -> GTAPVersion | V2: =+V5 -> BaseYear
B3: =SUBSTITUTE(ADDRESS(1,COLUMN(),4),1,) -> B | C3: =SUBSTITUTE(ADDRESS(1,COLUMN(),4),1,) -> C | D3: =SUBSTITUTE(ADDRESS(1,COLUMN(),4),"1","") -> D | G3: =SUBSTITUTE(ADDRESS(1,COLUMN(),4),"1","") -> G | H3: =SUBSTITUTE(ADDRESS(1,COLUMN(),4),"1","") -> H | I3: =SUBSTITUTE(ADDRESS(1,COLUMN(),4),"1","") -> I | J3: =SUBSTITUTE(ADDRESS(1,COLUMN(),4),"1","") -> J | K3: =SUBSTITUTE(ADDRESS(1,COLUMN(),4),"1","") -> K | L3: =SUBSTITUTE(ADDRESS(1,COLUMN(),4),"1","") -> L | M3: =SUBSTITUTE(ADDRESS(1,COLUMN(),4),"1","") -> M | N3: =SUBSTITUTE(ADDRESS(1,COLUMN(),4),"1","") -> N | ... Q3: =SUBSTITUTE(ADDRESS(1,COLUMN(),4),"1","") -> Q | S3: =SUBSTITUTE(ADDRESS(1,COLUMN(),4),"1","") -> S | T3: =SUBSTITUTE(ADDRESS(1,COLUMN(),4),"1","") -> T | U3: =SUBSTITUTE(ADDRESS(1,COLUMN(),4),"1","") -> U | V3: =SUBSTITUTE(ADDRESS(1,COLUMN(),4),"1","") -> V
B5: is | D5: aagr | G5: e | H5: l | I5: cap | J5: lnd | K5: natres | L5: inv | M5: ginv | N5: adpinv | O5: stb | P5: row | Q5: cohorts | S5: debt | T5: nrgfac | U5: GTAPVersion | V5: BaseYear
B6: a-pdr | C6: Paddy rice production | D6: agri | E6: agriculture | G6: c-p_c | H6: f-tech_aspros | I6: f-Capital | J6: f-Land | K6: f-NatlRes | L6: i-CGDS | M6: i-ginv | P6: w-ww_world | Q6: PLT15 | R6: Age lt 15 | S6: debt | T6: ener | U6: GTAPData9 | V6: 2014
B7: a-wht | C7: Wheat production | D7: allIndustry | E7: All industry | G7: c-coa | H7: f-clerks | J7: f-AEZ1 | Q7: P1564 | R7: Age 15-64
B8: a-gro | C8: Coarse grains production | D8: mine | E8: mining | G8: c-oil | H8: f-service_shop | J8: f-AEZ2 | Q8: P65UP | R8: Age gt 64
B9: a-v_f | C9: Fruits and vegetable production | D9: manu | E9: manufacturing | G9: c-gas | H9: f-off_mgr_pros | J9: f-AEZ3 | Q9: PTOTL | R9: All ages
B10: a-osd | C10: Oilseeds production | D10: hema | E10: heavy manufacturin | G10: c-ely | H10: f-ag_othlowsk | J10: f-AEZ4
B11: a-c_b | C11: Sugar cane and beet production | D11: ener | E11: energy | H11: f-m_tech_aspros | J11: f-AEZ5
B12: a-pfb | C12: Production of plant based fibres | D12: cons | E12: construction | H12: f-m_clerks | J12: f-AEZ6
B13: a-ocr | C13: Production of other crops | D13: allServices | E13: All services | H13: f-m_service_shop | J13: f-AEZ7
B14: a-ctl | C14: Ruminants for meat | D14: wast | E14: Waste and water | H14: f-m_off_mgr_pros | J14: f-AEZ8
B15: a-ctlRais | C15: Cattle raising | D15: trad | E15: Trade | H15: f-m_ag_othlowsk | J15: f-AEZ9
B16: a-oap | C16: Other animal production | D16: tran | E16: Transport | H16: f-f_tech_aspros | J16: f-AEZ10
B17: a-rmk | C17: Raw milk production | D17: serv | E17: services | H17: f-f_clerks | J17: f-AEZ11
B18: a-wol | C18: Wool production | D18: Taxes | E18: Taxes | H18: f-f_service_shop | J18: f-AEZ12
B19: a-frs | C19: Forestry production | D19: GrDomProd | E19: GDP | H19: f-f_off_mgr_pros | J19: f-AEZ13
B20: a-fsh | C20: Fisheries | D20: GrDomProdGro | E20: GDP Growth | H20: f-f_ag_othlowsk | J20: f-AEZ14
B21: a-coa | C21: Coal extraction | H21: f-m_skl | J21: f-AEZ15
B22: a-oil | C22: Oil extraction | H22: f-f_skl | J22: f-AEZ16
B23: a-gas | C23: Gas extraction | H23: f-m_nsk | J23: f-AEZ17
B24: a-omn | C24: Other extraction | H24: f-f_nsk | J24: f-AEZ18
B25: a-cmt | C25: Cattle meat production | J25: f-water
B26: a-omt | C26: Other meat production
B27: a-vol | C27: Vegetable oil and cake production
B28: a-mil | C28: Dairies
B29: a-pcr | C29: Rice processing
B30: a-sgr | C30: Sugar processing
B31: a-ofd | C31: Other food industries
B32: a-b_t | C32: Beverages and tobacco production
B33: a-tex | C33: Textile production
B34: a-wap | C34: Production of wearing apparel
B35: a-lea | C35: Production of leather
B36: a-lum | C36: Production of wood products
B37: a-ppp | C37: Paper and publishing industries
... B237: f-top | C237: Total production bundle
B238: na
B239: GHGs
B240: Acid
...

Sheet maps
A1: Maps
A2: =+A5 -> mapaGTAP | B2: =+B5 -> 0 | C2: =+C5 -> 0 | D2: =+D5 -> mapcGTAP | E2: =+E5 -> 0 | F2: =+F5 -> 0 | G2: =+G5 -> mapis | H2: =+H5 -> 0 | ... K2: =+K5 -> 0 | M2: =+M5 -> mapaagr | N2: =+N5 -> 0
A3: =+SUBSTITUTE(ADDRESS(1,COLUMN(),4),"1","") -> A | B3: =+SUBSTITUTE(ADDRESS(1,COLUMN(),4),"1","") -> B | C3: =+SUBSTITUTE(ADDRESS(1,COLUMN(),4),"1","") -> C | D3: =+SUBSTITUTE(ADDRESS(1,COLUMN(),4),"1","") -> D | E3: =+SUBSTITUTE(ADDRESS(1,COLUMN(),4),"1","") -> E | F3: =+SUBSTITUTE(ADDRESS(1,COLUMN(),4),"1","") -> F | G3: =+SUBSTITUTE(ADDRESS(1,COLUMN(),4),"1","") -> G | H3: =+SUBSTITUTE(ADDRESS(1,COLUMN(),4),"1","") -> H | ... K3: =+SUBSTITUTE(ADDRESS(1,COLUMN(),4),"1","") -> K | M3: =+SUBSTITUTE(ADDRESS(1,COLUMN(),4),"1","") -> M | N3: =+SUBSTITUTE(ADDRESS(1,COLUMN(),4),"1","") -> N
M4: h+f
A5: mapaGTAP | D5: mapcGTAP | G5: mapis | J5: maptax | M5: mapaagr
A6: pdr | B6: a-pdr_0 | D6: pdr | E6: c-pdr_0 | G6: a-pdr_0 | H6: a-pdr | J6: dtx | K6: t-DIRTAX | M6: agri | N6: a-pdr
A7: wht | B7: a-wht_0 | D7: wht | E7: c-wht_0 | G7: a-wht_0 | H7: a-wht | J7: ptx | K7: t-PRODTAX | M7: agri | N7: a-wht
A8: gro | B8: a-gro_0 | D8: gro | E8: c-gro_0 | G8: a-gro_0 | H8: a-gro | J8: stx | K8: t-stx | M8: agri | N8: a-gro
A9: v_f | B9: a-v_f_0 | D9: v_f | E9: c-v_f_0 | G9: a-v_f_0 | H9: a-v_f | J9: mtx | K9: t-imp | M9: agri | N9: a-v_f
A10: osd | B10: a-osd_0 | D10: osd | E10: c-osd_0 | G10: a-osd_0 | H10: a-osd | J10: vat | K10: na | M10: agri | N10: a-osd
A11: c_b | B11: a-c_b_0 | D11: c_b | E11: c-c_b_0 | G11: a-c_b_0 | H11: a-c_b | J11: ctx | K11: na | M11: agri | N11: a-c_b
A12: pfb | B12: a-pfb_0 | D12: pfb | E12: c-pfb_0 | G12: a-pfb_0 | H12: a-pfb | J12: psb | K12: na | M12: agri | N12: a-pfb
A13: ocr | B13: a-ocr_0 | D13: ocr | E13: c-ocr_0 | G13: a-ocr_0 | H13: a-ocr | J13: etx | K13: t-exp | M13: agri | N13: a-ocr
A14: ctl | B14: a-ctl_0 | D14: ctl | E14: c-ctl_0 | G14: a-ctl_0 | H14: a-ctl | J14: ssb | K14: na | M14: agri | N14: a-ctl
A15: ctl | B15: a-ctlRais_0 | D15: ctl | E15: c-ctlRais_0 | G15: a-ctlRais_0 | H15: a-ctlRais | M15: agri | N15: a-ctlRais
A16: oap | B16: a-oap_0 | D16: oap | E16: c-oap_0 | G16: a-oap_0 | H16: a-oap | M16: agri | N16: a-oap
A17: rmk | B17: a-rmk_0 | D17: rmk | E17: c-rmk_0 | G17: a-rmk_0 | H17: a-rmk | M17: agri | N17: a-rmk
A18: rmk | B18: a-ctlRais_0 | D18: rmk | E18: c-ctlRais_0 | G18: a-wol_0 | H18: a-wol | M18: agri | N18: a-wol
A19: wol | B19: a-wol_0 | D19: wol | E19: c-wol_0 | G19: a-frs_0 | H19: a-frs | M19: agri | N19: a-frs
A20: frs | B20: a-frs_0 | D20: frs | E20: c-frs_0 | G20: a-fsh_0 | H20: a-fsh | M20: agri | N20: a-fsh
A21: fsh | B21: a-fsh_0 | D21: fsh | E21: c-fsh_0 | G21: a-coa_0 | H21: a-coa | M21: mine | N21: a-oil
A22: coa | B22: a-coa_0 | D22: coa | E22: c-coa_0 | G22: a-oil_0 | H22: a-oil | M22: mine | N22: a-gas
A23: oil | B23: a-oil_0 | D23: oil | E23: c-oil_0 | G23: a-gas_0 | H23: a-gas | M23: mine | N23: a-coa
A24: gas | B24: a-gas_0 | D24: gas | E24: c-gas_0 | G24: a-omn_0 | H24: a-omn | M24: mine | N24: a-omn
A25: omn | B25: a-omn_0 | D25: omn | E25: c-omn_0 | G25: a-cmt_0 | H25: a-cmt | M25: manu | N25: a-cmt
A26: cmt | B26: a-cmt_0 | D26: cmt | E26: c-cmt_0 | G26: a-omt_0 | H26: a-omt | M26: manu | N26: a-omt
... A65: dwe | B65: a-dwe_0 | D65: dwe | E65: c-dwe_0 | G65: a-macc_0 | H65: a-macc | M65: serv | N65: a-macc
G66: a-care_0 | H66: a-care | M66: serv | N66: a-care
G67: c-pdr_0 | H67: c-pdr
G68: c-wht_0 | H68: c-wht
G69: c-gro_0 | H69: c-gro
G70: c-v_f_0 | H70: c-v_f
G71: c-osd_0 | H71: c-osd
G72: c-c_b_0 | H72: c-c_b
G73: c-pfb_0 | H73: c-pfb
G74: c-ocr_0 | H74: c-ocr
G75: c-ctl_0 | H75: c-ctl
G76: c-ctlRais_0 | H76: c-ctlRais
G77: c-oap_0 | H77: c-oap
G78: c-rmk_0 | H78: c-rmk
...

Sheet EmiInv
B1: co2 | C1: n2o | D1: ch4 | E1: fgas
A2: manu | B2: na
A3: agri
A4: Elec
A5: tran
B11: co2 | C11: n2o | D11: ch4
A12: Fugi | B12: na
A13: Indu
A14: Wast
A15: LUCF

Sheet mapK
C2: Crops | D2: MeatDairy | E2: FoodOther | F2: Clothing | G2: Manu | H2: Hot_Trad | I2: care_hht | J2: Serv | K2: privTrs | L2: privTrsEner | M2: privTrsRest | N2: Trans | O2: enerGas | P2: enerFossil | Q2: enerEle | R2: HousEner
C3: 0.5 | D3: 0.25 | E3: 0.25 | F3: 0.25 | G3: 0.25 | H3: 0.2 | I3: 2 | J3: 0.25 | K3: 0.1 | L3: eps | M3: 0.1 | N3: 0.25 | O3: 0.1 | P3: 0.25 | Q3: 0.1 | R3: 0.25
C5: Crops | D5: MeatDairy | E5: FoodOther | F5: Clothing | G5: Manu | H5: Hot_Trad | I5: care_hht | J5: Serv | K5: privTrs | L5: privTrsEner | M5: privTrsRest | N5: Trans | O5: enerGas | P5: enerFossil | Q5: EnerEle | R5: HousEner
B6: c-pdr | C6: 1
B7: c-wht | C7: 1
B8: c-gro | C8: 1
B9: c-v_f | C9: 1
B10: c-osd | C10: 1
B11: c-c_b | C11: 1
B12: c-ocr | C12: 1
B13: c-ctl | D13: 1
B14: c-ctlRais | D14: 1
B15: c-oap | D15: 1
B16: c-rmk | D16: 1
B17: c-fsh | D17: 1
B18: c-cmt | D18: 1
B19: c-omt | D19: 1
B20: c-mil | D20: 1
B21: c-trd | D21: 0.05 | E21: 0.1 | F21: 0.1 | G21: 0.05 | H21: 0.6 | M21: 0.1
B22: c-vol | E22: 1
B23: c-pcr | E23: 1
B24: c-sgr | E24: 1
B25: c-ofd | E25: 1
B26: c-b_t | E26: 1
B27: c-pfb | F27: 1
B28: c-wol | F28: 1
B29: c-tex | F29: 1
B30: c-lea | F30: 1
B31: c-wap | F31: 1
B32: c-frs | G32: 0.5 | R32: 0.5
B33: c-omn | G33: 1
B34: c-lum | G34: 1
B35: c-crp | G35: 1
B36: c-nmm | G36: 1
B37: c-i_s | G37: 1
B38: c-nfm | G38: 1
B39: c-fmp | G39: 1
B40: c-ele | G40: 1
B41: c-omf | G41: 1
B42: c-ppp | G42: 1
...

Sheet pnest
D2: labsk | E2: labus | F2: labsk_labus | G2: cap_labSk | H2: va | I2: cap_labsk_ener | J2: ener | K2: ely_tnd | L2: gas_gdt | M2: ener_gasoil | N2: ener_fossil | O2: aez_land | P2: crops | Q2: anim_meat | R2: f-top | S2: nd | T2: wtr_land | U2: nd_wtr_land | V2: crops_land
C3: subsElas | D3: 0.5 | E3: 0.5 | F3: 0.25 | G3: 0.2 | H3: 0.7 | I3: 0.25 | J3: 0.5 | K3: eps | L3: eps | M3: 0.7 | N3: 0.5 | O3: 7.5 | P3: 2 | Q3: 2 | R3: eps | S3: eps | T3: 0.5 | U3: 0.25 | V3: 0.5
C4: additive | J4: 1 | M4: 1 | N4: 1
D6: labsk | E6: labus | F6: labsk_labus | G6: cap_labSk | H6: va | I6: cap_labsk_ener | J6: ener | K6: ely_tnd | L6: gas_gdt | M6: ener_gasoil | N6: ener_fossil | O6: aez_land | P6: crops | Q6: anim_meat | R6: f-top | S6: nd | T6: wtr_land | U6: nd_wtr_land | V6: crops_land
B7: all | C7: f-off_mgr_pros | D7: 1
B8: all | C8: f-tech_aspros | D8: 1
B9: all | C9: f-m_off_mgr_pros | D9: 1
B10: all | C10: f-m_tech_aspros | D10: 1
B11: all | C11: f-f_off_mgr_pros | D11: 1
B12: all | C12: f-f_tech_aspros | D12: 1
B13: all | C13: f-m_skl | D13: 1
B14: all | C14: f-f_skl | D14: 1
B15: all | C15: f-clerks | E15: 1
B16: all | C16: f-service_shop | E16: 1
B17: all | C17: f-ag_othlowsk | E17: 1
B18: all | C18: f-m_clerks | E18: 1
B19: all | C19: f-m_service_shop | E19: 1
B20: all | C20: f-m_ag_othlowsk | E20: 1
B21: all | C21: f-f_clerks | E21: 1
B22: all | C22: f-f_service_shop | E22: 1
B23: all | C23: f-f_ag_othlowsk | E23: 1
B24: all | C24: f-m_nsk | E24: 1
B25: all | C25: f-f_nsk | E25: 1
B26: all | C26: labus | F26: 1
B27: all | C27: labsk | F27: 0.5 | G27: 0.5
B28: all | C28: f-Capital | G28: 1
B29: all | C29: f-NatlRes | H29: 1
B30: all | C30: labsk_labus | H30: 1
B31: all | C31: cap_labsk_ener | H31: 1
B32: all | C32: f-land | H32: 1
B33: all | C33: f-water | H33: 1 | T33: eps | U33: eps | V33: eps
B34: all | C34: aez_land | H34: 1
B35: a-pdr | C35: nd_wtr_land | H35: 1
B36: a-wht | C36: nd_wtr_land | H36: 1
B37: a-gro | C37: nd_wtr_land | H37: 1
B38: a-v_f | C38: nd_wtr_land | H38: 1
B39: a-osd | C39: nd_wtr_land | H39: 1
B40: a-c_b | C40: nd_wtr_land | H40: 1
B41: a-pfb | C41: nd_wtr_land | H41: 1
B42: a-ocr | C42: nd_wtr_land | H42: 1
...

Sheet defPar
A1: Explanation | B1: parameter | C1: value
A2: Elasticity between demand bundles other final Demand | B2: sigmaf0 | C2: 1.01
A3: Elasticity between savings and total consumption | B3: omegaSav0 | C3: 0.2
A4: Elasticity between savings and transfers to HHs | B4: omegaSavEntr0 | C4: 0.05
A5: Elasticity between government and private bonds | B5: omegaFund0 | C5: 4
A6: Elasticity of capital supply to capital stock | B6: epsRor0 | C6: eps
A7: Elasticity of expected return on capital to capital stock | B7: epsRorE0 | C7: 0.9
A8: Share of investment that is not added to capital stock | B8: PhiPcInv0 | C8: 0.75
A9: Depreciation rate | B9: depr0 | C9: 0.04
A10: Capital stock GDP ratio | B10: capoutRate0 | C10: 5
A11: Elasticity of labor productivity to air pollution | B11: AirpolEff0 | C11: 0.025
A12: Elasticity among commodities when an activity produces multiple commodities | B12: omegap0 | C12: 0.2
A13: Disinvestment Elasticity for declining sectors | B13: invElas0 | C13: 0.7
A14: Elasticity among activities when a commodity is produced by multiple activities | B14: sigmas0 | C14: inf
A15: Elasticity between imports and domestic demand | B15: sigmam0 | C15: 5
A16: Elasticity between exports and domestic supply | B16: omegax0 | C16: 3
A17: Elasticity between margin commodities | B17: sigmamg0 | C17: 0.01
A18: Import supply Elasticity | B18: omegam0 | C18: inf
A19: Export demand Elasticity | B19: etae0 | C19: inf
A20: debt to gdp default threshhold, used in specific savf closure | B20: omegasavf0 | C20: 0.5
A21: positive scaling parameter, used in specific savf closure | B21: rhosavf0 | C21: 10
A22: Country risk premium | B22: riskPrem0 | C22: 1
A23: expected return rate in the row | B23: retrow0 | C23: 0.05
A24: expected per capita GDP growth rate in the row | B24: ggdppcrow0 | C24: 0.02
A25: efficiency param. returns | B25: eta10 | C25: 7
A26: efficiency param. GDP p.c. growth | B26: eta20 | C26: 7
A27: efficiency param. returns | B27: eta1a0 | C27: 7
A28: efficiency param. GDP p.c. growth | B28: eta2a0 | C28: 7
A29: Elasticity of foreign new public debt to interest rate | B29: sigmaFInt0 | C29: 1
A30: Threshold after which gov consumption is dampended | B30: debtGdpTgt0 | C30: 0.5
A31: Default income elasticity for aggregate commodity group (overwritten by hohpar) | B31: incElas0 | C31: 0.735
... A42: Elasticity of stock changes to targeted stock over production | B42: rhoXDelSt0 | C42: 0.25
A43: Target stock over production level | B43: alphaSt0 | C43: eps

Sheet fmNest
C1: Only used if AEZ not found | D1: Only used if AEZ not found | E1: Only used if AEZ not found | F1: Only used if AEZ not found | H1: Immobile; Numbers for activities are activity specific factor supply elasticities | J1: All activities not in agrLab and manulab, automatically assigned to not listed activities | K1: All activities, automatically assigned to all actibitiy as no entry | L1: All activities, automatically assigned to all actibitiy as no entry | M1: All labor categories have the segments defined agrLab, manuLab, restLab | R1: All labor categories have the segments defined agrLab, manuLab, restLab | W1: All labor categories have the segments defined agrLab, manuLab, restLab | AB1: Gender differentiated labor and the 5 skill levels are never active simultaneously | AW1: cropLand by AEZ | BO1: grassland by AEZ | CG1: agrland by AEZ | CY1: Total land by AEZ, aggregated to aez_land (total land) in production function
C2: cropLand | D2: grasLand | E2: agrLand | F2: f-land | G2: agrLab | H2: f-natlRes | I2: manuLab | J2: restLab | K2: f-capital | L2: f-water | M2: f-tech_aspros | N2: f-service_shop | O2: f-off_mgr_pros | P2: f-ag_othlowsk | Q2: f-clerks | R2: f-m_tech_aspros | S2: f-m_service_shop | T2: f-m_off_mgr_pros | U2: f-m_ag_othlowsk | V2: f-m_clerks | W2: f-f_tech_aspros | X2: f-f_service_shop | Y2: f-f_off_mgr_pros | Z2: f-f_ag_othlowsk | AA2: f-f_clerks | AB2: f-m_skl | AC2: f-f_skl | AD2: f-m_nsk | AE2: f-f_nsk | AF2: f-f_tech_aspros_rest | AG2: f-f_service_shop_rest | AH2: f-f_off_mgr_pros_rest | AI2: f-f_ag_othlowsk_rest | AJ2: f-f_clerks_rest | AK2: f-f_skl_rest | AL2: f-f_nsk_rest | AM2: f-f_tech_aspros_care | AN2: f-f_service_shop_care | AO2: f-f_off_mgr_pros_care | AP2: f-f_ag_othlowsk_care | AQ2: f-f_clerks_care | AR2: f-f_skl_care | AS2: f-f_nsk_care | AT2: AEZ1_cropLand | AU2: AEZ2_cropLand | AV2: AEZ3_cropLand | AW2: AEZ4_cropLand | AX2: AEZ5_cropLand | AY2: AEZ6_cropLand | AZ2: AEZ7_cropLand | BA2: AEZ8_cropLand | BB2: AEZ9_cropLand | BC2: AEZ10_cropLand | BD2: AEZ11_cropLand | BE2: AEZ12_cropLand | BF2: AEZ13_cropLand | BG2: AEZ14_cropLand | BH2: AEZ15_cropLand | BI2: AEZ16_cropLand | BJ2: AEZ17_cropLand | BK2: AEZ18_cropLand | BL2: AEZ1_grasLand | BM2: AEZ2_grasLand | BN2: AEZ3_grasLand | BO2: AEZ4_grasLand | BP2: AEZ5_grasLand | BQ2: AEZ6_grasLand | BR2: AEZ7_grasLand | BS2: AEZ8_grasLand | BT2: AEZ9_grasLand | BU2: AEZ10_grasLand | BV2: AEZ11_grasLand | BW2: AEZ12_grasLand | BX2: AEZ13_grasLand | BY2: AEZ14_grasLand | BZ2: AEZ15_grasLand | CA2: AEZ16_grasLand | CB2: AEZ17_grasLand | CC2: AEZ18_grasLand | CD2: AEZ1_agrLand | CE2: AEZ2_agrLand | CF2: AEZ3_agrLand | CG2: AEZ4_agrLand | CH2: AEZ5_agrLand | CI2: AEZ6_agrLand | CJ2: AEZ7_agrLand | CK2: AEZ8_agrLand | CL2: AEZ9_agrLand | CM2: AEZ10_agrLand | CN2: AEZ11_agrLand | CO2: AEZ12_agrLand | CP2: AEZ13_agrLand | CQ2: AEZ14_agrLand | CR2: AEZ15_agrLand | CS2: AEZ16_agrLand | CT2: AEZ17_agrLand | CU2: AEZ18_agrLand | CV2: f-AEZ1 | CW2: f-AEZ2 | CX2: f-AEZ3 | CY2: f-AEZ4 | CZ2: f-AEZ5 | DA2: f-AEZ6 | DB2: f-AEZ7 | DC2: f-AEZ8 | DD2: f-AEZ9 | DE2: f-AEZ10 | DF2: f-AEZ11 | DG2: f-AEZ12 | DH2: f-AEZ13 | DI2: f-AEZ14 | DJ2: f-AEZ15 | DK2: f-AEZ16 | DL2: f-AEZ17 | DM2: f-AEZ18
B3: additive | C3: 1 | D3: 1 | E3: 1 | F3: 1 | AT3: 1 | AU3: 1 | AV3: 1 | AW3: 1 | AX3: 1 | AY3: 1 | AZ3: 1 | BA3: 1 | BB3: 1 | BC3: 1 | BD3: 1 | BE3: 1 | BF3: 1 | BG3: 1 | BH3: 1 | BI3: 1 | BJ3: 1 | BK3: 1 | BL3: 1 | BM3: 1 | BN3: 1 | BO3: 1 | BP3: 1 | BQ3: 1 | BR3: 1 | BS3: 1 | BT3: 1 | BU3: 1 | BV3: 1 | BW3: 1 | BX3: 1 | BY3: 1 | BZ3: 1 | CA3: 1 | CB3: 1 | CC3: 1 | CD3: 1 | CE3: 1 | CF3: 1 | CG3: 1 | CH3: 1 | CI3: 1 | CJ3: 1 | CK3: 1 | CL3: 1 | CM3: 1 | CN3: 1 | CO3: 1 | CP3: 1 | CQ3: 1 | CR3: 1 | CS3: 1 | CT3: 1 | CU3: 1 | CV3: 1 | CW3: 1 | CX3: 1 | CY3: 1 | CZ3: 1 | DA3: 1 | DB3: 1 | DC3: 1 | DD3: 1 | DE3: 1 | DF3: 1 | DG3: 1 | DH3: 1 | DI3: 1 | DJ3: 1 | DK3: 1 | DL3: 1 | DM3: 1
B4: omegaCET | C4: 0.75 | D4: 0.75 | E4: 0.5 | F4: 0.25 | G4: inf | H4: eps | I4: inf | J4: inf | K4: inf | L4: 0.75 | M4: 2 | N4: 2 | O4: 2 | P4: 2 | Q4: 2 | R4: 2 | S4: 2 | T4: 2 | U4: 2 | V4: 2 | W4: 0.5 | X4: 0.5 | Y4: 0.5 | Z4: 0.5 | AA4: 0.5 | AB4: 2 | AC4: 0.5 | AD4: 2 | AE4: 0.5 | AF4: inf | AG4: inf | AH4: inf | AI4: inf | AJ4: inf | AK4: inf | AL4: inf | AM4: eps | AN4: eps | AO4: eps | AP4: eps | AQ4: eps | AR4: eps | AS4: eps | AT4: 0.75 | AU4: 0.75 | AV4: 0.75 | AW4: 0.75 | AX4: 0.75 | AY4: 0.75 | AZ4: 0.75 | BA4: 0.75 | BB4: 0.75 | BC4: 0.75 | BD4: 0.75 | BE4: 0.75 | BF4: 0.75 | BG4: 0.75 | BH4: 0.75 | BI4: 0.75 | BJ4: 0.75 | BK4: 0.75 | BL4: 0.75 | BM4: 0.75 | BN4: 0.75 | BO4: 0.75 | BP4: 0.75 | BQ4: 0.75 | BR4: 0.75 | BS4: 0.75 | BT4: 0.75 | BU4: 0.75 | BV4: 0.75 | BW4: 0.75 | BX4: 0.75 | BY4: 0.75 | BZ4: 0.75 | CA4: 0.75 | CB4: 0.75 | CC4: 0.75 | CD4: 0.5 | CE4: 0.5 | CF4: 0.5 | CG4: 0.5 | CH4: 0.5 | CI4: 0.5 | CJ4: 0.5 | CK4: 0.5 | CL4: 0.5 | CM4: 0.5 | CN4: 0.5 | CO4: 0.5 | CP4: 0.5 | CQ4: 0.5 | CR4: 0.5 | CS4: 0.5 | CT4: 0.5 | CU4: 0.5 | CV4: 0.25 | CW4: 0.25 | CX4: 0.25 | CY4: 0.25 | CZ4: 0.25 | DA4: 0.25 | DB4: 0.25 | DC4: 0.25 | DD4: 0.25 | DE4: 0.25 | DF4: 0.25 | DG4: 0.25 | DH4: 0.25 | DI4: 0.25 | DJ4: 0.25 | DK4: 0.25 | DL4: 0.25 | DM4: 0.25
B5: omegaCETShort | C5: eps | D5: eps | E5: eps | F5: eps | G5: eps | H5: eps | I5: 1.01 | J5: 1.01 | K5: eps | L5: 0.25 | M5: 1.01 | N5: 1.01 | O5: 1.01 | P5: 1.01 | Q5: 1.01 | R5: 1.01 | S5: 1.01 | T5: 1.01 | U5: 1.01 | V5: 1.01 | W5: 0.05 | X5: 0.05 | Y5: 0.05 | Z5: 0.05 | AA5: 0.05 | AB5: 1.01 | AC5: 0.05 | AD5: 1.01 | AE5: 0.05 | AF5: 1.01 | AG5: 1.01 | AH5: 1.01 | AI5: 1.01 | AJ5: 1.01 | AK5: 1.01 | AL5: 1.01 | AM5: eps | AN5: eps | AO5: eps | AP5: eps | AQ5: eps | AR5: eps | AS5: eps | AT5: 0.75 | AU5: 0.75 | AV5: 0.75 | AW5: 0.75 | AX5: 0.75 | AY5: 0.75 | AZ5: 0.75 | BA5: 0.75 | BB5: 0.75 | BC5: 0.75 | BD5: 0.75 | BE5: 0.75 | BF5: 0.75 | BG5: 0.75 | BH5: 0.75 | BI5: 0.75 | BJ5: eps | BK5: eps | BL5: 0.75 | BM5: 0.75 | BN5: 0.75 | BO5: 0.75 | BP5: 0.75 | BQ5: 0.75 | BR5: 0.75 | BS5: 0.75 | BT5: 0.75 | BU5: 0.75 | BV5: 0.75 | BW5: 0.75 | BX5: 0.75 | BY5: 0.75 | BZ5: 0.75 | CA5: 0.75 | CB5: 0.75 | CC5: 0.75 | CD5: 0.5 | CE5: 0.5 | CF5: 0.5 | CG5: 0.5 | CH5: 0.5 | CI5: 0.5 | CJ5: 0.5 | CK5: 0.5 | CL5: 0.5 | CM5: 0.5 | CN5: 0.5 | CO5: 0.5 | CP5: 0.5 | CQ5: 0.5 | CR5: 0.5 | CS5: 0.5 | CT5: 0.5 | CU5: 0.5 | CV5: eps | CW5: eps | CX5: eps | CY5: eps | CZ5: eps | DA5: eps | DB5: eps | DC5: eps | DD5: eps | DE5: eps | DF5: eps | DG5: eps | DH5: eps | DI5: eps | DJ5: eps | DK5: eps | DL5: eps | DM5: eps
B6: factSupElas | F6: 0.1 | M6: 0.2 | N6: 0.2 | O6: 0.2 | P6: 0.2 | Q6: 0.2 | R6: 0.2 | S6: 0.2 | T6: 0.2 | U6: 0.2 | V6: 0.2 | W6: 0.2 | X6: 0.2 | Y6: 0.2 | Z6: 0.2 | AA6: 0.2 | AB6: 0.2 | AC6: 0.2 | AD6: 0.2 | AE6: 0.2 | CV6: 0.1 | CW6: 0.1 | CX6: 0.1 | CY6: 0.1 | CZ6: 0.1 | DA6: 0.1 | DB6: 0.1 | DC6: 0.1 | DD6: 0.1 | DE6: 0.1 | DF6: 0.1 | DG6: 0.1 | DH6: 0.1 | DI6: 0.1 | DJ6: 0.1 | DK6: 0.1 | DL6: 0.1 | DM6: 0.1
B7: factSupElasShort | F7: eps | L7: 0.01 | M7: eps | N7: eps | O7: eps | P7: eps | Q7: eps | R7: eps | S7: eps | T7: eps | U7: eps | V7: eps | W7: eps | X7: eps | Y7: eps | Z7: eps | AA7: eps | AB7: eps | AC7: eps | AD7: eps | AE7: eps | CV7: eps | CW7: eps | CX7: eps | CY7: eps | CZ7: eps | DA7: eps | DB7: eps | DC7: eps | DD7: eps | DE7: eps | DF7: eps | DG7: eps | DH7: eps | DI7: eps | DJ7: eps | DK7: eps | DL7: eps | DM7: eps
C9: cropLand | D9: grasLand | E9: agrLand | F9: f-land | G9: agrLab | H9: f-natlRes | I9: manuLab | J9: restLab | K9: f-capital | L9: f-water | M9: f-tech_aspros | N9: f-service_shop | O9: f-off_mgr_pros | P9: f-ag_othlowsk | Q9: f-clerks | R9: f-m_tech_aspros | S9: f-m_service_shop | T9: f-m_off_mgr_pros | U9: f-m_ag_othlowsk | V9: f-m_clerks | W9: f-f_tech_aspros | X9: f-f_service_shop | Y9: f-f_off_mgr_pros | Z9: f-f_ag_othlowsk | AA9: f-f_clerks | AB9: f-m_skl | AC9: f-f_skl | AD9: f-m_nsk | AE9: f-f_nsk | AF9: f-f_tech_aspros_rest | AG9: f-f_service_shop_rest | AH9: f-f_off_mgr_pros_rest | AI9: f-f_ag_othlowsk_rest | AJ9: f-f_clerks_rest | AK9: f-f_skl_rest | AL9: f-f_nsk_rest | AM9: f-f_tech_aspros_care | AN9: f-f_service_shop_care | AO9: f-f_off_mgr_pros_care | AP9: f-f_ag_othlowsk_care | AQ9: f-f_clerks_care | AR9: f-f_skl_care | AS9: f-f_nsk_care | AT9: AEZ1_cropLand | AU9: AEZ2_cropLand | AV9: AEZ3_cropLand | AW9: AEZ4_cropLand | AX9: AEZ5_cropLand | AY9: AEZ6_cropLand | AZ9: AEZ7_cropLand | BA9: AEZ8_cropLand | BB9: AEZ9_cropLand | BC9: AEZ10_cropLand | BD9: AEZ11_cropLand | BE9: AEZ12_cropLand | BF9: AEZ13_cropLand | BG9: AEZ14_cropLand | BH9: AEZ15_cropLand | BI9: AEZ16_cropLand | BJ9: AEZ17_cropLand | BK9: AEZ18_cropLand | BL9: AEZ1_grasLand | BM9: AEZ2_grasLand | BN9: AEZ3_grasLand | BO9: AEZ4_grasLand | BP9: AEZ5_grasLand | BQ9: AEZ6_grasLand | BR9: AEZ7_grasLand | BS9: AEZ8_grasLand | BT9: AEZ9_grasLand | BU9: AEZ10_grasLand | BV9: AEZ11_grasLand | BW9: AEZ12_grasLand | BX9: AEZ13_grasLand | BY9: AEZ14_grasLand | BZ9: AEZ15_grasLand | CA9: AEZ16_grasLand | CB9: AEZ17_grasLand | CC9: AEZ18_grasLand | CD9: AEZ1_agrLand | CE9: AEZ2_agrLand | CF9: AEZ3_agrLand | CG9: AEZ4_agrLand | CH9: AEZ5_agrLand | CI9: AEZ6_agrLand | CJ9: AEZ7_agrLand | CK9: AEZ8_agrLand | CL9: AEZ9_agrLand | CM9: AEZ10_agrLand | CN9: AEZ11_agrLand | CO9: AEZ12_agrLand | CP9: AEZ13_agrLand | CQ9: AEZ14_agrLand | CR9: AEZ15_agrLand | CS9: AEZ16_agrLand | CT9: AEZ17_agrLand | CU9: AEZ18_agrLand | CV9: f-AEZ1 | CW9: f-AEZ2 | CX9: f-AEZ3 | CY9: f-AEZ4 | CZ9: f-AEZ5 | DA9: f-AEZ6 | DB9: f-AEZ7 | DC9: f-AEZ8 | DD9: f-AEZ9 | DE9: f-AEZ10 | DF9: f-AEZ11 | DG9: f-AEZ12 | DH9: f-AEZ13 | DI9: f-AEZ14 | DJ9: f-AEZ15 | DK9: f-AEZ16 | DL9: f-AEZ17 | DM9: f-AEZ18
B10: a-care | AM10: 1 | AN10: 1 | AO10: 1 | AP10: 1 | AQ10: 1 | AR10: 1 | AS10: 1
B11: a-pdr | C11: 1 | G11: 1 | AT11: 1 | AU11: 1 | AV11: 1 | AW11: 1 | AX11: 1 | AY11: 1 | AZ11: 1 | BA11: 1 | BB11: 1 | BC11: 1 | BD11: 1 | BE11: 1 | BF11: 1 | BG11: 1 | BH11: 1 | BI11: 1 | BJ11: 1 | BK11: 1
B12: a-wht | C12: 1 | G12: 1 | AT12: 1 | AU12: 1 | AV12: 1 | AW12: 1 | AX12: 1 | AY12: 1 | AZ12: 1 | BA12: 1 | BB12: 1 | BC12: 1 | BD12: 1 | BE12: 1 | BF12: 1 | BG12: 1 | BH12: 1 | BI12: 1 | BJ12: 1 | BK12: 1
B13: a-gro | C13: 1 | G13: 1 | AT13: 1 | AU13: 1 | AV13: 1 | AW13: 1 | AX13: 1 | AY13: 1 | AZ13: 1 | BA13: 1 | BB13: 1 | BC13: 1 | BD13: 1 | BE13: 1 | BF13: 1 | BG13: 1 | BH13: 1 | BI13: 1 | BJ13: 1 | BK13: 1
B14: a-v_f | C14: 1 | G14: 1 | AT14: 1 | AU14: 1 | AV14: 1 | AW14: 1 | AX14: 1 | AY14: 1 | AZ14: 1 | BA14: 1 | BB14: 1 | BC14: 1 | BD14: 1 | BE14: 1 | BF14: 1 | BG14: 1 | BH14: 1 | BI14: 1 | BJ14: 1 | BK14: 1
B15: a-osd | C15: 1 | G15: 1 | AT15: 1 | AU15: 1 | AV15: 1 | AW15: 1 | AX15: 1 | AY15: 1 | AZ15: 1 | BA15: 1 | BB15: 1 | BC15: 1 | BD15: 1 | BE15: 1 | BF15: 1 | BG15: 1 | BH15: 1 | BI15: 1 | BJ15: 1 | BK15: 1
B16: a-c_b | C16: 1 | G16: 1 | AT16: 1 | AU16: 1 | AV16: 1 | AW16: 1 | AX16: 1 | AY16: 1 | AZ16: 1 | BA16: 1 | BB16: 1 | BC16: 1 | BD16: 1 | BE16: 1 | BF16: 1 | BG16: 1 | BH16: 1 | BI16: 1 | BJ16: 1 | BK16: 1
B17: a-pfb | C17: 1 | G17: 1 | AT17: 1 | AU17: 1 | AV17: 1 | AW17: 1 | AX17: 1 | AY17: 1 | AZ17: 1 | BA17: 1 | BB17: 1 | BC17: 1 | BD17: 1 | BE17: 1 | BF17: 1 | BG17: 1 | BH17: 1 | BI17: 1 | BJ17: 1 | BK17: 1
B18: a-ocr | C18: 1 | G18: 1 | AT18: 1 | AU18: 1 | AV18: 1 | AW18: 1 | AX18: 1 | AY18: 1 | AZ18: 1 | BA18: 1 | BB18: 1 | BC18: 1 | BD18: 1 | BE18: 1 | BF18: 1 | BG18: 1 | BH18: 1 | BI18: 1 | BJ18: 1 | BK18: 1
B19: a-ctl | D19: 1 | G19: 1 | BL19: 1 | BM19: 1 | BN19: 1 | BO19: 1 | BP19: 1 | BQ19: 1 | BR19: 1 | BS19: 1 | BT19: 1 | BU19: 1 | BV19: 1 | BW19: 1 | BX19: 1 | BY19: 1 | BZ19: 1 | CA19: 1 | CB19: 1 | CC19: 1
B20: a-oap | D20: 1 | G20: 1 | BL20: 1 | BM20: 1 | BN20: 1 | BO20: 1 | BP20: 1 | BQ20: 1 | BR20: 1 | BS20: 1 | BT20: 1 | BU20: 1 | BV20: 1 | BW20: 1 | BX20: 1 | BY20: 1 | BZ20: 1 | CA20: 1 | CB20: 1 | CC20: 1
B21: a-rmk | D21: 1 | G21: 1 | BL21: 1 | BM21: 1 | BN21: 1 | BO21: 1 | BP21: 1 | BQ21: 1 | BR21: 1 | BS21: 1 | BT21: 1 | BU21: 1 | BV21: 1 | BW21: 1 | BX21: 1 | BY21: 1 | BZ21: 1 | CA21: 1 | CB21: 1 | CC21: 1
B22: a-ctlRais | D22: 1 | G22: 1 | BL22: 1 | BM22: 1 | BN22: 1 | BO22: 1 | BP22: 1 | BQ22: 1 | BR22: 1 | BS22: 1 | BT22: 1 | BU22: 1 | BV22: 1 | BW22: 1 | BX22: 1 | BY22: 1 | BZ22: 1 | CA22: 1 | CB22: 1 | CC22: 1
B23: a-wol | D23: 1 | G23: 1 | BL23: 1 | BM23: 1 | BN23: 1 | BO23: 1 | BP23: 1 | BQ23: 1 | BR23: 1 | BS23: 1 | BT23: 1 | BU23: 1 | BV23: 1 | BW23: 1 | BX23: 1 | BY23: 1 | BZ23: 1 | CA23: 1 | CB23: 1 | CC23: 1
B24: cropLand | E24: 1
B25: grasLand | E25: 1
B26: a-frs | F26: 1 | H26: 0.25 | I26: 1 | CV26: 1 | CW26: 1 | CX26: 1 | CY26: 1 | CZ26: 1 | DA26: 1 | DB26: 1 | DC26: 1 | DD26: 1 | DE26: 1 | DF26: 1 | DG26: 1 | DH26: 1 | DI26: 1 | DJ26: 1 | DK26: 1 | DL26: 1 | DM26: 1
B27: agrLand | F27: 1
B28: a-fsh | H28: 0.25 | I28: 1
B29: a-coa | H29: 0.25 | I29: 1
B30: a-oil | H30: 0.25 | I30: 1
B31: a-gas | H31: 0.25 | I31: 1
B32: a-omn | H32: 0.25 | I32: 1
B33: a-cmt | I33: 1
B34: a-omt | I34: 1
B35: a-vol | I35: 1
B36: a-mil | I36: 1
B37: a-pcr | I37: 1
B38: a-sgr | I38: 1
B39: a-ofd | I39: 1
B40: a-b_t | I40: 1
B41: a-tex | I41: 1
...

Sheet actPar
B1: va | C1: va | D1: cap_labsk_ener | E1: cap_labsk_ener | F1: depr | G1: ener | H1: physProd | I1: capital | J1: labor
B2: Old | C2: New | D2: Old | E2: New | I2: intensMargElas | J2: intensMargElas
A3: a-PDR | B3: 0.195804 | C3: 0.522144 | D3: 0.1 | E3: 0.8 | F3: 0.038661729 | H3: 2451.707 | I3: 0.05 | J3: 0.1
A4: a-WHT | B4: 0.195804 | C4: 0.522144 | D4: 0.1 | E4: 0.8 | F4: 0.038661729 | H4: 50.467 | I4: 0.05 | J4: 0.1
A5: a-GRO | B5: 0.195804 | C5: 0.522144 | D5: 0.1 | E5: 0.8 | F5: 0.038661729 | H5: 7873.1803 | I5: 0.05 | J5: 0.1
A6: a-V_F | B6: 0.195804 | C6: 0.522144 | D6: 0.1 | E6: 0.8 | F6: 0.038661729 | I6: 0.05 | J6: 0.1
A7: a-OSD | B7: 0.195804 | C7: 0.522144 | D7: 0.1 | E7: 0.8 | F7: 0.038661729 | I7: 0.05 | J7: 0.1
A8: a-C_B | B8: 0.195804 | C8: 0.522144 | D8: 0.1 | E8: 0.8 | F8: 0.038661729 | H8: 3060.61 | I8: 0.05 | J8: 0.1
A9: a-PFB | B9: 0.195804 | C9: 0.522144 | D9: 0.1 | E9: 0.8 | F9: 0.038661729 | H9: 111.46869 | I9: 0.05 | J9: 0.1
A10: a-OCR | B10: 0.195804 | C10: 0.522144 | D10: 0.1 | E10: 0.8 | F10: 0.038661729 | I10: 0.05 | J10: 0.1
A11: a-CTL | B11: 0.195804 | C11: 0.522144 | D11: 0.1 | E11: 0.8 | F11: 0.096654321 | H11: 8643.198 | I11: 0.05 | J11: 0.1
A12: a-OAP | B12: 0.195804 | C12: 0.522144 | D12: 0.1 | E12: 0.8 | F12: 0.057992593 | H12: 579.954 | I12: 0.05 | J12: 0.1
A13: a-RMK | B13: 0.195804 | C13: 0.522144 | D13: 0.1 | E13: 0.8 | F13: 0.096654321 | H13: 2301.6378 | I13: 0.05 | J13: 0.1
A14: a-WOL | B14: 0.195804 | C14: 0.522144 | D14: 0.1 | E14: 0.8 | F14: 0.096654321 | H14: 7.3094567 | I14: 0.05 | J14: 0.1
A15: a-FRS | B15: 0.15 | C15: 0.4 | D15: 0.1 | E15: 0.8 | F15: 0.038661729 | I15: 0.05 | J15: 0.1
A16: a-FSH | B16: 0.15 | C16: 0.4 | D16: 0.1 | E16: 0.8 | F16: 0.038661729 | I16: 0.05 | J16: 0.1
A17: a-COA | B17: 0.15 | C17: 0.4 | D17: 0.1 | E17: 0.8 | F17: 0.038661729 | I17: 0.05 | J17: 0.1
A18: a-OIL | B18: 0.15 | C18: 0.4 | D18: 0.1 | E18: 0.8 | F18: 0.038661729 | I18: 0.05 | J18: 0.1
A19: a-GAS | B19: 0.15 | C19: 0.4 | D19: 0.1 | E19: 0.8 | F19: 0.038661729 | I19: 0.05 | J19: 0.1
A20: a-OMN | B20: 0.15 | C20: 0.4 | D20: 0.1 | E20: 0.8 | F20: 0.038661729 | I20: 0.05 | J20: 0.1
A21: a-CMT | B21: 0.74 | C21: 2.24 | D21: 0.1 | E21: 0.8 | F21: 0.038661729 | H21: 496.29367 | I21: 0.05 | J21: 0.1
A22: a-OMT | B22: 0.74 | C22: 2.24 | D22: 0.1 | E22: 0.8 | F22: 0.038661729 | H22: 213.06187 | I22: 0.05 | J22: 0.1
A23: a-VOL | B23: 0.74 | C23: 2.24 | D23: 0.1 | E23: 0.8 | F23: 0.038661729 | I23: 0.05 | J23: 0.1
A24: a-MIL | B24: 0.74 | C24: 2.24 | D24: 0.1 | E24: 0.8 | F24: 0.038661729 | I24: 0.05 | J24: 0.1
A25: a-PCR | B25: 0.74 | C25: 2.24 | D25: 0.1 | E25: 0.8 | F25: 0.038661729 | I25: 0.05 | J25: 0.1
A26: a-SGR | B26: 0.74 | C26: 2.24 | D26: 0.1 | E26: 0.8 | F26: 0.038661729 | I26: 0.05 | J26: 0.1
A27: a-OFD | B27: 0.74 | C27: 2.24 | D27: 0.1 | E27: 0.8 | F27: 0.038661729 | I27: 0.05 | J27: 0.1
A28: a-B_T | B28: 0.74 | C28: 2.24 | D28: 0.1 | E28: 0.8 | F28: 0.038661729 | I28: 0.05 | J28: 0.1
A29: a-TEX | B29: 0.85 | C29: 2.52 | D29: 0.1 | E29: 0.8 | F29: 0.038661729 | I29: 0.05 | J29: 0.1
A30: a-WAP | B30: 0.85 | C30: 2.52 | D30: 0.1 | E30: 0.8 | F30: 0.038661729 | I30: 0.05 | J30: 0.1
A31: a-LEA | B31: 0.85 | C31: 2.52 | D31: 0.1 | E31: 0.8 | F31: 0.038661729 | I31: 0.05 | J31: 0.1
A32: a-LUM | B32: 0.85 | C32: 2.52 | D32: 0.1 | E32: 0.8 | F32: 0.038661729 | I32: 0.05 | J32: 0.1
A33: a-PPP | B33: 0.85 | C33: 2.52 | D33: 0.1 | E33: 0.8 | F33: 0.038661729 | I33: 0.05 | J33: 0.1
A34: a-P_C | B34: 0.85 | C34: 2.52 | D34: 0.1 | E34: 0.8 | F34: 0.038661729 | I34: 0.05 | J34: 0.1
... A49: a-TRD | B49: 1.26 | C49: 3.36 | D49: 0.1 | E49: 0.8 | F49: 0.038661729 | I49: 0.05 | J49: 0.1
A50: a-OTP | B50: 1.26 | C50: 3.36 | D50: 0.1 | E50: 0.8 | F50: 0.038661729 | G50: Eps | I50: 0.05 | J50: 0.1
A51: a-WTP | B51: 1.26 | C51: 3.36 | D51: 0.1 | E51: 0.8 | F51: 0.038661729 | I51: 0.05 | J51: 0.1
A52: a-ATP | B52: 1.26 | C52: 3.36 | D52: 0.1 | E52: 0.8 | F52: 0.038661729 | I52: 0.05 | J52: 0.1
A53: a-CMN | B53: 0.85 | C53: 2.52 | D53: 0.1 | E53: 0.8 | F53: 0.038661729 | I53: 0.05 | J53: 0.1
A54: a-OFI | B54: 0.85 | C54: 2.52 | D54: 0.1 | E54: 0.8 | F54: 0.038661729 | I54: 0.05 | J54: 0.1
...

Sheet comPar
B1: sigmas0 | C1: sigmam0 | D1: omegax0 | E1: sigmamg0 | F1: omegam0 | G1: etae0 | H1: alphaST0 | I1: rhoPDelSt0 | J1: rhoXDelSt0
A2: c-pdr | C2: 5.05 | D2: 5.05 | H2: 0.4
A3: c-wht | C3: 4.45 | D3: 4.45 | H3: 0.4
A4: c-gro | C4: 1.3 | D4: 1.3 | H4: 0.4
A5: c-v_f | C5: 1.85 | D5: 1.85 | H5: 0.4
A6: c-osd | C6: 2.45 | D6: 2.45 | H6: 0.4
A7: c-c_b | C7: 2.7 | D7: 2.7 | H7: 0.4
A8: c-pfb | C8: 2.5 | D8: 2.5 | H8: 0.4
A9: c-ocr | C9: 3.25 | D9: 3.25 | H9: 0.4
A10: c-ctl | C10: 2 | D10: 2
A11: c-oap | C11: 1.3 | D11: 1.3
A12: c-rmk | C12: 3.65 | D12: 3.65
A13: c-wol | C13: 6.45 | D13: 6.45
A14: c-frs | C14: 2.5 | D14: 2.5
A15: c-fsh | C15: 1.25 | D15: 1.25
A16: c-coa | C16: 3.05 | D16: 3.05
A17: c-oil | C17: 5.2 | D17: 5.2
A18: c-gas | C18: 10 | D18: 10 | M18: original: 17.5
A19: c-omn | C19: 0.9 | D19: 0.9
A20: c-cmt | C20: 3.85 | D20: 3.85
A21: c-omt | C21: 4.4 | D21: 4.4
A22: c-vol | C22: 3.3 | D22: 3.3
A23: c-mil | C23: 3.65 | D23: 3.65
A24: c-pcr | C24: 2.6 | D24: 2.6
A25: c-sgr | C25: 2.7 | D25: 2.7
A26: c-ofd | C26: 2 | D26: 2
A27: c-b_t | C27: 1.15 | D27: 1.15
A28: c-tex | C28: 3.75 | D28: 3.75
A29: c-wap | C29: 3.7 | D29: 3.7
A30: c-lea | C30: 4.05 | D30: 4.05
... A43: c-omf | C43: 3.75 | D43: 3.75
A44: c-ely | B44: 5 | C44: 2.8 | D44: 2.8
A45: c-gdt | C45: 2.8 | D45: 2.8
A46: c-wtr | C46: 2.8 | D46: 2.8
A47: c-cns | C47: 1.9 | D47: 1.9
A48: c-trd | C48: 1.9 | D48: 1.9
A49: c-otp | B49: 2 | C49: 1.9 | D49: 1.9
A50: c-wtp | C50: 1.9 | D50: 1.9
A51: c-atp | C51: 1.9 | D51: 1.9
A52: c-cmn | C52: 1.9 | D52: 1.9
...

Sheet hohPar
B1: Estimated regresion function for GTAP incp and subp parameters of CDE demand system as a function of log(GDP)
C3: Crops | D3: MeatDairy | E3: FoodOther | F3: Clothing | G3: Manu | H3: HousEner | I3: Hot_Trad | J3: Serv | K3: Trans
A4: incp | B4: logGdp | C4: -0.35989833 | D4: -0.2626742 | E4: -0.2535079 | F4: -0.26211887 | G4: -0.0038737402 | H4: -0.12280265 | I4: -0.48752412 | J4: -0.32878554 | K4: -0.22094564
A5: incp | B5: constant | C5: 1.6029705 | D5: 1.6297386 | E5: 1.4684957 | F5: 1.6155831 | G5: 1.0268112 | H5: 1.5567056 | I5: 3.3439665 | J5: 2.5574108 | K5: 1.8364509
A6: subP | B6: logGdp | C6: 0.078237188 | D6: -0.28871033 | E6: -0.2565631 | F6: -0.28728804 | G6: -0.35529065 | H6: -0.33566719 | I6: -0.28736376 | J6: -0.30851208 | K6: -0.32077306
A7: subP | B7: constant | C7: 0.62104646 | D7: 1.7137944 | E7: 1.6471096 | F7: 1.7118797 | G7: 1.8671344 | H7: 1.7781962 | I7: 1.5435341 | J7: 1.6471142 | K7: 1.7411171
C9: incElas0 | D9: incElas0 | E9: incElas0 | F9: incElas0 | G9: incElas0 | H9: incElas0 | I9: incElas0 | J9: incElas0 | K9: incElas0 | L9: incElas0 | M9: incElas0 | N9: incElas0 | O9: incElas0 | P9: prcElas0 | Q9: prcElas0 | R9: prcElas0 | S9: prcElas0 | T9: prcElas0 | U9: prcElas0 | V9: prcElas0 | W9: prcElas0 | X9: prcElas0 | Y9: prcElas0 | Z9: prcElas0 | AA9: prcElas0 | AB9: prcElas0
C10: Crops | D10: MeatDairy | E10: FoodOther | F10: Clothing | G10: Manu | H10: Ener | I10: Hot_Trad | J10: Serv | K10: Tran | L10: tranEner | M10: TranRest | N10: enerFossil | O10: EnerEle | P10: Crops | Q10: MeatDairy | R10: FoodOther | S10: Clothing | T10: Manu | U10: Ener | V10: Hot_Rest | W10: Serv | X10: Tran | Y10: tranEner | Z10: TranRest | AA10: enerFossil | AB10: EnerEle
B11: h-hhold | C11: 0.0099869975 | D11: 0.89252515 | E11: 0.81242082 | F11: 0.88586466 | G11: 1.0296549 | H11: 1.0306813 | I11: 1.0556798 | J11: 1.0430201 | K11: 1.0088102 | L11: 1.0099849 | M11: 1.0099849 | N11: 1.0099849 | O11: 1.0099849 | P11: -0.0089340869 | Q11: -0.72893442 | R11: -0.6781994 | S11: -0.72932814 | T11: -0.85781901 | U11: -0.83648713 | V11: -0.88422525 | W11: -0.90886187 | X11: -0.82599099 | Y11: -0.99661607 | Z11: -0.99451842 | AA11: -0.99911067 | AB11: -0.99778749
D15: a-PDR | E15: a-WHT | F15: a-GRO | G15: a-V_F | H15: a-OSD | I15: a-C_B | J15: a-PFB | K15: a-OCR | L15: a-CTL | M15: a-OAP | N15: a-RMK | O15: a-WOL | P15: a-FRS | Q15: a-FSH | R15: a-COA | S15: a-OIL | T15: a-GAS | U15: a-OXT | V15: a-CMT | W15: a-OMT | X15: a-VOL | Y15: a-MIL | Z15: a-PCR | AA15: a-SGR | AB15: a-OFD | AC15: a-B_T | AD15: a-TEX | AE15: a-WAP | AF15: a-LEA | AG15: a-LUM | AH15: a-PPP | AI15: a-P_C | AJ15: a-CHM | AK15: a-BPH | AL15: a-RPP | AM15: a-NMM | AN15: a-I_S | AO15: a-NFM | AP15: a-FMP | AQ15: a-ELE | AR15: a-EEQ | AS15: a-OME | AT15: a-MVH | AU15: a-OTN | AV15: a-OMF | AW15: a-TnD | AX15: a-NuclearBL | AY15: a-CoalBL | AZ15: a-GasBL | BA15: a-WindBL | BB15: a-HydroBL | BC15: a-OilBL | BD15: a-OtherBL | BE15: a-GasP | BF15: a-HydroP | BG15: a-OilP | BH15: a-SolarP | BI15: a-GDT | BJ15: a-WTR | BK15: a-CNS | BL15: a-TRD | BM15: a-AFS | BN15: a-OTP | BO15: a-WTP | BP15: a-ATP | BQ15: a-WHS | BR15: a-CMN | BS15: a-OFI | BT15: a-INS | BU15: a-RSA | BV15: a-OBS | BW15: a-ROS | BX15: a-OSG | BY15: a-EDU | BZ15: a-HHT | CA15: a-DWE | CB15: a-ctlRais | CC15: a-otpEle | CD15: a-macc
B16: h-hhold | C16: f-tech_aspros | D16: eps
B17: g-govt | C17: f-tech_aspros
B18: e-ent | C18: f-tech_aspros

Sheet GDPComposition

Sheet EnTech
A1: size of stepping on toes effect | D1: supernormal growth | G1: Varia
A2: larger value = smaller R&D response to change in revenue; 1 = no response; no value = R&D mechanism is switched off | D2: difference between the productivity growth of the sector and the balanced growth path of the economy; 0 = the sector does not grow faster
A3: PhiRDtoes | D3: Supfgrowth
A5: a-ely | B5: 0.3 | D5: a-ely | E5: 0.02 | G5: PrvRD | H5: 0.02 | J5: Private R&D share of GDP
G6: rhoEn | H6: 0.06 | J6: fraction of innovations that go to inventions (inventions are not bounded by the frontier)
G7: sigmaxpvt | H7: 0.5 | J7: elasticity of substitution between processes
G8: obsol | H8: 0.2 | J8: baseyear obsolescence rate
G9: fgrowthDef | H9: 0.01 | J9: growth of the frontier
G10: interestRD | H10: 0.03 | J10: interest rate considered by the R&D firms

Sheet othPar
B1: sigmaf0
A2: g-govt
A3: i-CGDS
A4: i-ginv

Sheet GHGMitigation
C1: 2017 | D1: =+C1+1 -> 2018 | E1: =+D1+1 -> 2019 | F1: =+E1+1 -> 2020 | G1: =+F1+1 -> 2021 | H1: =+G1+1 -> 2022 | I1: =+H1+1 -> 2023 | J1: =+I1+1 -> 2024 | K1: =+J1+1 -> 2025 | ... CH1: =+CG1+1 -> 2100
A2: BAU | B2: carbonTax | C2: 0.5 | D2: =+C2+0.5 -> 1 | E2: =+D2+0.5 -> 1.5 | F2: =+E2+0.5 -> 2 | G2: =+F2+0.5 -> 2.5 | H2: =+G2+0.5 -> 3 | I2: =+H2+0.5 -> 3.5 | J2: =+I2+0.5 -> 4 | K2: =+J2+0.5 -> 4.5 | ... CH2: =+CG2+0.5 -> 42
A3: BAU | B3: ceilingBench | C3: 1 | D3: =+MAX(+C3-0.02,0.0000000001) -> 0.98 | E3: =+MAX(+D3-0.02,0.0000000001) -> 0.96 | F3: =+MAX(+E3-0.02,0.0000000001) -> 0.94 | G3: =+MAX(+F3-0.02,0.0000000001) -> 0.92 | H3: =+MAX(+G3-0.02,0.0000000001) -> 0.9 | I3: =+MAX(+H3-0.02,0.0000000001) -> 0.88 | J3: =+MAX(+I3-0.02,0.0000000001) -> 0.86 | K3: =+MAX(+J3-0.02,0.0000000001) -> 0.84 | ... CH3: =+MAX(+CG3-0.02,0.0000000001) -> 1e-10
A4: BAU | B4: ceilingBaseline | C4: 1 | D4: =+MAX(+C4-0.02,0.0000000001) -> 0.98 | E4: =+MAX(+D4-0.02,0.0000000001) -> 0.96 | F4: =+MAX(+E4-0.02,0.0000000001) -> 0.94 | G4: =+MAX(+F4-0.02,0.0000000001) -> 0.92 | H4: =+MAX(+G4-0.02,0.0000000001) -> 0.9 | I4: =+MAX(+H4-0.02,0.0000000001) -> 0.88 | J4: =+MAX(+I4-0.02,0.0000000001) -> 0.86 | K4: =+MAX(+J4-0.02,0.0000000001) -> 0.84 | ... CH4: =+MAX(+CG4-0.02,0.0000000001) -> 1e-10
A5: BAU | B5: ceilingAbsolute

Sheet Energy

Sheet SAM

Sheet Labor
B1: a-pdr_0
A2: f-tech_aspros_0 | B2: 1e-20
