Workbook
Name PRINT_AREA_MI: #REF!

Sheet Layout
A1: LAYOUT
A3: Data Type | B3: Name | C3: Location | D3: Row dimension | E3: Column dimension | F3: Total dimension
D4: rdim | E4: cdim | F4: dim
G5: se=0
A6: dset | B6: ac | C6: =IF(A6="dset","Sets!"&HLOOKUP(B6,Sets!$A$2:$AZ$3,2,)&6,IF(A6="set","Maps!"&HLOOKUP(B6,Sets!$A$2:$AZ$3,2,)&6)) -> Sets!A6 | D6: 1
A7: dset | B7: c | C7: =IF(A7="dset","Sets!"&HLOOKUP(B7,Sets!$A$2:$AZ$3,2,)&6,IF(A7="set","Maps!"&HLOOKUP(B7,Sets!$A$2:$AZ$3,2,)&6)) -> Sets!F6 | D7: 1
A8: dset | B8: mrgn | C8: =IF(A8="dset","Sets!"&HLOOKUP(B8,Sets!$A$2:$AZ$3,2,)&6,IF(A8="set","Maps!"&HLOOKUP(B8,Sets!$A$2:$AZ$3,2,)&6)) -> Sets!G6 | D8: 1
A9: dset | B9: a | C9: =IF(A9="dset","Sets!"&HLOOKUP(B9,Sets!$A$2:$AZ$3,2,)&6,IF(A9="set","Maps!"&HLOOKUP(B9,Sets!$A$2:$AZ$3,2,)&6)) -> Sets!H6 | D9: 1
A10: dset | B10: f | C10: =IF(A10="dset","Sets!"&HLOOKUP(B10,Sets!$A$2:$AZ$3,2,)&6,IF(A10="set","Maps!"&HLOOKUP(B10,Sets!$A$2:$AZ$3,2,)&6)) -> Sets!I6 | D10: 1
A11: dset | B11: l | C11: =IF(A11="dset","Sets!"&HLOOKUP(B11,Sets!$A$2:$AZ$3,2,)&6,IF(A11="set","Maps!"&HLOOKUP(B11,Sets!$A$2:$AZ$3,2,)&6)) -> Sets!J6 | D11: 1
A12: dset | B12: k | C12: =IF(A12="dset","Sets!"&HLOOKUP(B12,Sets!$A$2:$AZ$3,2,)&6,IF(A12="set","Maps!"&HLOOKUP(B12,Sets!$A$2:$AZ$3,2,)&6)) -> Sets!K6 | D12: 1
A13: dset | B13: h | C13: =IF(A13="dset","Sets!"&HLOOKUP(B13,Sets!$A$2:$AZ$3,2,)&6,IF(A13="set","Maps!"&HLOOKUP(B13,Sets!$A$2:$AZ$3,2,)&6)) -> Sets!L6 | D13: 1
A14: dset | B14: g | C14: =IF(A14="dset","Sets!"&HLOOKUP(B14,Sets!$A$2:$AZ$3,2,)&6,IF(A14="set","Maps!"&HLOOKUP(B14,Sets!$A$2:$AZ$3,2,)&6)) -> Sets!M6 | D14: 1
A15: dset | B15: gtind | C15: =IF(A15="dset","Sets!"&HLOOKUP(B15,Sets!$A$2:$AZ$3,2,)&6,IF(A15="set","Maps!"&HLOOKUP(B15,Sets!$A$2:$AZ$3,2,)&6)) -> Sets!O6 | D15: 1
A16: dset | B16: gtdir | C16: =IF(A16="dset","Sets!"&HLOOKUP(B16,Sets!$A$2:$AZ$3,2,)&6,IF(A16="set","Maps!"&HLOOKUP(B16,Sets!$A$2:$AZ$3,2,)&6)) -> Sets!P6 | D16: 1
A17: dset | B17: e | C17: =IF(A17="dset","Sets!"&HLOOKUP(B17,Sets!$A$2:$AZ$3,2,)&6,IF(A17="set","Maps!"&HLOOKUP(B17,Sets!$A$2:$AZ$3,2,)&6)) -> Sets!Q6 | D17: 1
A18: dset | B18: i | C18: =IF(A18="dset","Sets!"&HLOOKUP(B18,Sets!$A$2:$AZ$3,2,)&6,IF(A18="set","Maps!"&HLOOKUP(B18,Sets!$A$2:$AZ$3,2,)&6)) -> Sets!R6 | D18: 1
A19: dset | B19: gINV | C19: ="Sets!"&HLOOKUP(B19,Sets!$A$2:$AZ$3,2,)&6 -> Sets!S6 | D19: 1
A20: dset | B20: w | C20: =IF(A20="dset","Sets!"&HLOOKUP(B20,Sets!$A$2:$AZ$3,2,)&6,IF(A20="set","Maps!"&HLOOKUP(B20,Sets!$A$2:$AZ$3,2,)&6)) -> Sets!T6 | D20: 1
A21: dset | B21: acm | C21: =IF(A21="dset","Sets!"&HLOOKUP(B21,Sets!$A$2:$AZ$3,2,)&6,IF(A21="set","Maps!"&HLOOKUP(B21,Sets!$A$2:$AZ$3,2,)&6)) -> Sets!V6 | D21: 1
A22: dset | B22: emrgn | C22: =IF(A22="dset","Sets!"&HLOOKUP(B22,Sets!$A$2:$AZ$3,2,)&6,IF(A22="set","Maps!"&HLOOKUP(B22,Sets!$A$2:$AZ$3,2,)&6)) -> Sets!W6 | D22: 1
A23: dset | B23: etax | C23: =IF(A23="dset","Sets!"&HLOOKUP(B23,Sets!$A$2:$AZ$3,2,)&6,IF(A23="set","Maps!"&HLOOKUP(B23,Sets!$A$2:$AZ$3,2,)&6)) -> Sets!X6 | D23: 1
A24: par | B24: macsam2 | C24: macro-sam!a3 | D24: 1 | E24: 1
A25: dset | B25: macro | C25: macro!A6 | D25: 1
A26: par | B26: macromat | C26: macro!A6 | D26: 1
A27: par | B27: SAMIni | C27: Proto-SAM!A1 | D27: 1 | E27: 1
A28: par | B28: macscale | C28: macro-sam!B1 | F28: 0
A29: par | B29: splitShr | C29: splitShr!C5 | D29: 2 | E29: 2
A30: set | B30: map_acIni_ac | C30: ="Sets!"&HLOOKUP(B30,Sets!$A$2:$AZ$3,2,)&6 -> Sets!C6 | D30: 2
A31: dset | B31: gt | C31: ="Sets!"&HLOOKUP(B31,Sets!$A$2:$AZ$3,2,)&6 -> Sets!N6 | D31: 1
A32: set | B32: macmap3 | C32: ="Sets!"&HLOOKUP(B32,Sets!$A$2:$AZ$3,2,)&6 -> Sets!AA6 | D32: 2
A33: set | B33: asplit_gtap | C33: sets!AG6 | D33: 1
A34: set | B34: csplit_gtap | C34: sets!AH6 | D34: 1
A35: set | B35: aciniMac | C35: sets!AF6 | D35: 1
A36: set | B36: map_acIni_acini | C36: ="Sets!"&HLOOKUP(B36,Sets!$A$2:$AZ$3,2,)&6 -> Sets!AD6 | D36: 2
A37: set | B37: map_aG_ac | C37: ="Sets!"&HLOOKUP(B37,Sets!$A$2:$BJ$3,2,)&6 -> Sets!AJ6 | D37: 2
A38: set | B38: map_cG_ac | C38: ="Sets!"&HLOOKUP(B38,Sets!$A$2:$BG$3,2,)&6 -> Sets!AM6 | D38: 2
A39: set | B39: map_fG_ac | C39: ="Sets!"&HLOOKUP(B39,Sets!$A$2:$BG$3,2,)&6 -> Sets!AP6 | D39: 2
A40: set | B40: map_a_c | C40: ="Sets!"&HLOOKUP(B40,Sets!$A$2:$BG$3,2,)&6 -> Sets!AS6 | D40: 2
A41: par | B41: fixes | C41: Fixes!A1 | D41: 2

Sheet SplitShr

Sheet Sets
A1: Model Specific Sets | C1: Model Specific Sets | F1: CMDTY3 | G1: MRGN3 | H1: ACTVTY3 | I1: FCTR3 | J1: LBR3 | K1: KPTL3 | L1: HHLD3 | M1: GOVT3 | O1: ITAX3 | P1: DTAX3 | Q1: ENTRP3 | R1: i-INVST3 | S1: Gi-INVST3 | T1: WRLD3 | U1: TOTAL3
A2: =+A5 -> AC | C2: =+C5 -> map_acIni_ac | D2: =+D5 -> 0 | E2: =+E5 -> 0 | F2: =+F5 -> c | G2: =+G5 -> mrgn | H2: =+H5 -> a | I2: =+I5 -> f | J2: =+J5 -> l | ... AE2: =+AE5 -> 0 | AF2: acIniMac | AG2: =+AG5 -> asplit_gtap | AH2: =+AH5 -> csplit_gtap | AI2: =+AI5 -> 0 | AJ2: =+AJ5 -> map_aG_ac | AK2: =+AK5 -> 0 | AL2: =+AL5 -> 0 | AM2: =+AM5 -> map_cG_ac | AN2: =+AN5 -> 0 | ... AV2: =+AV5 -> 0
A3: =SUBSTITUTE(ADDRESS(1,COLUMN(),4),"1","") -> A | C3: =SUBSTITUTE(ADDRESS(1,COLUMN(),4),"1","") -> C | D3: =SUBSTITUTE(ADDRESS(1,COLUMN(),4),"1","") -> D | E3: =SUBSTITUTE(ADDRESS(1,COLUMN(),4),"1","") -> E | F3: =SUBSTITUTE(ADDRESS(1,COLUMN(),4),"1","") -> F | G3: =SUBSTITUTE(ADDRESS(1,COLUMN(),4),"1","") -> G | H3: =SUBSTITUTE(ADDRESS(1,COLUMN(),4),"1","") -> H | I3: =SUBSTITUTE(ADDRESS(1,COLUMN(),4),"1","") -> I | J3: =SUBSTITUTE(ADDRESS(1,COLUMN(),4),"1","") -> J | ... AV3: =SUBSTITUTE(ADDRESS(1,COLUMN(),4),"1","") -> AV
A4: GAMS Name | F4: Commodities | G4: Margins | H4: Activities | I4: Factors | J4: Labour Factors | K4: Capital Factors | L4: Households | M4: Government | O4: Indirect taxes | P4: Direct taxes | Q4: Enterprises | R4: Savings INVestment | T4: Trade | V4: Macro-sam accounts | W4: Export margins | X4: Export taxes | AG4: Acts split with GTAP | AH4: Comm. Split with GTGAP
A5: AC | C5: map_acIni_ac | F5: c | G5: mrgn | H5: a | I5: f | J5: l | K5: k | L5: h | M5: g | N5: gt | O5: gtind | P5: gtdir | Q5: e | R5: i | S5: gINV | T5: w | V5: acm | W5: emrgn | X5: etax | AA5: macmap3 | AD5: map_acIni_acini | AF5: acIniMac | AG5: asplit_gtap | AH5: csplit_gtap | AJ5: map_aG_ac | AM5: map_cG_ac | AP5: map_fG_ac | AS5: map_a_c
A6: a-pdr_0 | C6: a-pdr_i | D6: a-pdr_0 | F6: c-pdr_0 | G6: m-otp_0 | H6: a-pdr_0 | I6: f-Land_0 | J6: f-tech_aspros_0 | K6: f-Capital_0 | L6: h-hhold_0 | M6: g-govt_0 | N6: t-tf_E1Land_0 | O6: t-tf_E1Land_0 | P6: t-DIRTAX_0 | Q6: e-ent_0 | R6: i-CGDS_0 | S6: i-ginv_0 | T6: w-ww_world_0 | V6: MAACT3 | AA6: MAACT3 | AB6: a-pdr_0 | AD6: a-pdr_i | AE6: a-pdr_i | AG6: a-TnD-0 | AH6: c-TnD-0 | AJ6: pdr | AK6: a-cere-0 | AM6: pdr | AN6: c-cere-0 | AP6: tap | AQ6: f-labskf-0 | AS6: a-pdr_0 | AT6: c-pdr_0
A7: a-wht_0 | C7: a-wht_i | D7: a-wht_0 | F7: c-wht_0 | G7: m-wtp_0 | H7: a-wht_0 | I7: f-tech_aspros_0 | J7: f-clerks_0 | N7: t-tf_E2tech_as_0 | O7: t-tf_E2tech_as_0 | V7: MCCOM3 | AA7: MAACT3 | AB7: a-wht_0 | AD7: a-wht_i | AE7: a-wht_i | AG7: a-eGB-0 | AH7: c-elec-0 | AJ7: wht | AK7: a-cere-0 | AM7: wht | AN7: c-cere-0 | AP7: tap | AQ7: f-labski-0 | AS7: a-wht_0 | AT7: c-wht_0
A8: a-gro_0 | C8: a-gro_i | D8: a-gro_0 | F8: c-gro_0 | G8: m-atp_0 | H8: a-gro_0 | I8: f-clerks_0 | J8: f-service_shop_0 | N8: t-tf_E3clerks_0 | O8: t-tf_E3clerks_0 | V8: MRGN3 | AA8: MAACT3 | AB8: a-gro_0 | AD8: a-gro_i | AE8: a-gro_i | AG8: a-eWB-0 | AJ8: gro | AK8: a-cere-0 | AM8: gro | AN8: c-cere-0 | AP8: clk | AQ8: f-labsef-0 | AS8: a-gro_0 | AT8: c-gro_0
A9: a-v_f_0 | C9: a-v_f_i | D9: a-v_f_0 | F9: c-v_f_0 | H9: a-v_f_0 | I9: f-service_shop_0 | J9: f-off_mgr_pros_0 | N9: t-tf_E4service_0 | O9: t-tf_E4service_0 | V9: LBR3 | AA9: MAACT3 | AB9: a-v_f_0 | AD9: a-v_f_i | AE9: a-v_f_i | AG9: a-eHB-0 | AJ9: v_f | AK9: a-tube-0 | AM9: v_f | AN9: c-tube-0 | AP9: clk | AQ9: f-labsei-0 | AS9: a-v_f_0 | AT9: c-v_f_0
A10: a-osd_0 | C10: a-osd_i | D10: a-osd_0 | F10: c-osd_0 | H10: a-osd_0 | I10: f-off_mgr_pros_0 | J10: f-ag_othlowsk_0 | N10: t-tf_E5off_mgr_0 | O10: t-tf_E5off_mgr_0 | V10: KPTL3 | AA10: MAACT3 | AB10: a-osd_0 | AD10: a-osd_i | AE10: a-osd_i | AG10: a-eOB-0 | AJ10: osd | AK10: a-olea-0 | AM10: osd | AN10: c-olea-0 | AP10: svc | AQ10: f-labsef-0 | AS10: a-osd_0 | AT10: c-osd_0
A11: a-c_b_0 | C11: a-c_b_i | D11: a-c_b_0 | F11: c-c_b_0 | H11: a-c_b_0 | I11: f-ag_othlowsk_0 | N11: t-tf_E6ag_othl_0 | O11: t-tf_E6ag_othl_0 | V11: LAND3 | AA11: MAACT3 | AB11: a-c_b_0 | AD11: a-c_b_i | AE11: a-c_b_i | AG11: a-eOP-0 | AJ11: c_b | AK11: a-olea-0 | AM11: c_b | AN11: c-olea-0 | AP11: svc | AQ11: f-labsei-0 | AS11: a-c_b_0 | AT11: c-c_b_0
A12: a-pfb_0 | C12: a-pfb_i | D12: a-pfb_0 | F12: c-pfb_0 | H12: a-pfb_0 | I12: f-Capital_0 | N12: t-tf_E7Capital_0 | O12: t-tf_E7Capital_0 | V12: HHLD3 | AA12: MAACT3 | AB12: a-pfb_0 | AD12: a-pfb_i | AE12: a-pfb_i | AG12: a-eSo-0 | AJ12: pfb | AK12: a-olea-0 | AM12: pfb | AN12: c-olea-0 | AP12: off | AQ12: f-labskf-0 | AS12: a-pfb_0 | AT12: c-pfb_0
A13: a-ocr_0 | C13: a-ocr_i | D13: a-ocr_0 | F13: c-ocr_0 | H13: a-ocr_0 | I13: f-NatlRes_0 | N13: t-tf_E8NatlRes_0 | O13: t-tf_E8NatlRes_0 | V13: ENTRP3 | AA13: MAACT3 | AB13: a-ocr_0 | AD13: a-ocr_i | AE13: a-ocr_i | AJ13: ocr | AK13: a-flow-0 | AM13: ocr | AN13: c-flow-0 | AP13: off | AQ13: f-labski-0 | AS13: a-ocr_0 | AT13: c-ocr_0
A14: a-ctl_0 | C14: a-ctl_i | D14: a-ctl_0 | F14: c-ctl_0 | H14: a-ctl_0 | N14: t-tf_F_skl_0 | O14: t-tf_F_skl_0 | V14: GOVT3 | AA14: MAACT3 | AB14: a-ctl_0 | AD14: a-ctl_i | AE14: a-ctl_i | AJ14: ocr | AK14: a-cbcc-0 | AM14: ocr | AN14: c-cbcc-0 | AP14: agr | AQ14: f-labunf-0 | AS14: a-ctl_0 | AT14: c-ctl_0
A15: a-oap_0 | C15: a-oap_i | D15: a-oap_0 | F15: c-oap_0 | H15: a-oap_0 | N15: t-tf_M_skl_0 | O15: t-tf_M_skl_0 | V15: TAXPROD | AA15: MAACT3 | AB15: a-oap_0 | AD15: a-oap_i | AE15: a-oap_i | AJ15: pdr | AK15: a-auxc-0 | AM15: pdr | AN15: c-auxc-0 | AP15: agr | AQ15: f-labuni-0 | AS15: a-oap_0 | AT15: c-oap_0
A16: a-rmk_0 | C16: a-rmk_i | D16: a-rmk_0 | F16: c-rmk_0 | H16: a-rmk_0 | N16: t-tf_F_nsk_0 | O16: t-tf_F_nsk_0 | V16: TAXSUBS | AA16: MAACT3 | AB16: a-rmk_0 | AD16: a-rmk_i | AE16: a-rmk_i | AJ16: wht | AK16: a-auxc-0 | AM16: wht | AN16: c-auxc-0 | AP16: CAP | AQ16: f-cap-0 | AS16: a-rmk_0 | AT16: c-rmk_0
A17: a-wol_0 | C17: a-wol_i | D17: a-wol_0 | F17: c-wol_0 | H17: a-wol_0 | N17: t-tf_M_nsk_0 | O17: t-tf_M_nsk_0 | V17: TAXDIRECT | AA17: MAACT3 | AB17: a-wol_0 | AD17: a-wol_i | AE17: a-wol_i | AJ17: gro | AK17: a-auxc-0 | AM17: gro | AN17: c-auxc-0 | AP17: LAN | AQ17: f-cap-0 | AS17: a-wol_0 | AT17: c-wol_0
A18: a-frs_0 | C18: a-frs_i | D18: a-frs_0 | F18: c-frs_0 | H18: a-frs_0 | N18: t-tee_world_0 | O18: t-tee_world_0 | V18: TAXSALES | AA18: MAACT3 | AB18: a-frs_0 | AD18: a-frs_i | AE18: a-frs_i | AJ18: v_f | AK18: a-auxc-0 | AM18: v_f | AN18: c-auxc-0 | AP18: NTR | AQ18: f-cap-0 | AS18: a-frs_0 | AT18: c-frs_0
A19: a-fsh_0 | C19: a-fsh_i | D19: a-fsh_0 | F19: c-fsh_0 | H19: a-fsh_0 | N19: t-tmm_world_0 | O19: t-tmm_world_0 | V19: TAXVAT | AA19: MAACT3 | AB19: a-fsh_0 | AD19: a-fsh_i | AE19: a-fsh_i | AJ19: osd | AK19: a-auxc-0 | AM19: osd | AN19: c-auxc-0 | AS19: a-fsh_0 | AT19: c-fsh_0
A20: a-coa_0 | C20: a-coa_i | D20: a-coa_0 | F20: c-coa_0 | H20: a-coa_0 | N20: t-PRODTAX_0 | O20: t-PRODTAX_0 | V20: TAXIMPO | AA20: MAACT3 | AB20: a-coa_0 | AD20: a-coa_i | AE20: a-coa_i | AJ20: c_b | AK20: a-auxc-0 | AM20: c_b | AN20: c-auxc-0 | AS20: a-coa_0 | AT20: c-coa_0
A21: a-oil_0 | C21: a-oil_i | D21: a-oil_0 | F21: c-oil_0 | H21: a-oil_0 | N21: t-tssm_0 | O21: t-tssm_0 | V21: TAXEXPO | AA21: MAACT3 | AB21: a-oil_0 | AD21: a-oil_i | AE21: a-oil_i | AJ21: pfb | AK21: a-auxc-0 | AM21: pfb | AN21: c-auxc-0 | AS21: a-oil_0 | AT21: c-oil_0
A22: a-gas_0 | C22: a-gas_i | D22: a-gas_0 | F22: c-gas_0 | H22: a-gas_0 | N22: t-tssd_0 | O22: t-tssd_0 | V22: COMMSUBS | AA22: MAACT3 | AB22: a-gas_0 | AD22: a-gas_i | AE22: a-gas_i | AJ22: ocr | AK22: a-auxc-0 | AM22: ocr | AN22: c-auxc-0 | AS22: a-gas_0 | AT22: c-gas_0
A23: a-oxt_0 | C23: a-oxt_i | D23: a-oxt_0 | F23: c-oxt_0 | H23: a-oxt_0 | V23: TAXFACT | AA23: MAACT3 | AB23: a-oxt_0 | AD23: a-oxt_i | AE23: a-oxt_i | AJ23: ctl | AK23: a-livs-0 | AM23: ctl | AN23: c-livs-0 | AS23: a-oxt_0 | AT23: c-oxt_0
A24: a-cmt_0 | C24: a-cmt_i | D24: a-cmt_0 | F24: c-cmt_0 | H24: a-cmt_0 | V24: INVST3 | AA24: MAACT3 | AB24: a-cmt_0 | AD24: a-cmt_i | AE24: a-cmt_i | AJ24: oap | AK24: a-livs-0 | AM24: oap | AN24: c-livs-0 | AS24: a-cmt_0 | AT24: c-cmt_0
A25: a-omt_0 | C25: a-omt_i | D25: a-omt_0 | F25: c-omt_0 | H25: a-omt_0 | V25: GINVT3 | AA25: MAACT3 | AB25: a-omt_0 | AD25: a-omt_i | AE25: a-omt_i | AJ25: rmk | AK25: a-livs-0 | AM25: rmk | AN25: c-livs-0 | AS25: a-omt_0 | AT25: c-omt_0
A26: a-vol_0 | C26: a-vol_i | D26: a-vol_0 | F26: c-vol_0 | H26: a-vol_0 | V26: DELST3 | AA26: MAACT3 | AB26: a-vol_0 | AD26: a-vol_i | AE26: a-vol_i | AJ26: wol | AK26: a-livs-0 | AM26: wol | AN26: c-livs-0 | AS26: a-vol_0 | AT26: c-vol_0
A27: a-mil_0 | C27: a-mil_i | D27: a-mil_0 | F27: c-mil_0 | H27: a-mil_0 | V27: DEBT3 | AA27: MAACT3 | AB27: a-mil_0 | AD27: a-mil_i | AE27: a-mil_i | AJ27: frs | AK27: a-fore-0 | AM27: frs | AN27: c-fore-0 | AS27: a-mil_0 | AT27: c-mil_0
A28: a-pcr_0 | C28: a-pcr_i | D28: a-pcr_0 | F28: c-pcr_0 | H28: a-pcr_0 | V28: WRLD3 | AA28: MAACT3 | AB28: a-pcr_0 | AD28: a-pcr_i | AE28: a-pcr_i | AJ28: fsh | AK28: a-cama-0 | AM28: fsh | AN28: c-cama-0 | AS28: a-pcr_0 | AT28: c-pcr_0
A29: a-sgr_0 | C29: a-sgr_i | D29: a-sgr_0 | F29: c-sgr_0 | H29: a-sgr_0 | V29: total3 | AA29: MAACT3 | AB29: a-sgr_0 | AD29: a-sgr_i | AE29: a-sgr_i | AJ29: fsh | AK29: a-fish-0 | AM29: fsh | AN29: c-fish-0 | AS29: a-sgr_0 | AT29: c-sgr_0
A30: a-ofd_0 | C30: a-ofd_i | D30: a-ofd_0 | F30: c-ofd_0 | H30: a-ofd_0 | V30: other3 | AA30: MAACT3 | AB30: a-ofd_0 | AD30: a-ofd_i | AE30: a-ofd_i | AJ30: fsh | AK30: a-acui-0 | AM30: fsh | AN30: c-acui-0 | AS30: a-ofd_0 | AT30: c-ofd_0
A31: a-b_t_0 | C31: a-b_t_i | D31: a-b_t_0 | F31: c-b_t_0 | H31: a-b_t_0 | AA31: MAACT3 | AB31: a-b_t_0 | AD31: a-b_t_i | AE31: a-b_t_i | AJ31: coa | AK31: a-nmet-0 | AM31: coa | AN31: c-nmet-0 | AS31: a-b_t_0 | AT31: c-b_t_0
A32: a-tex_0 | C32: a-tex_i | D32: a-tex_0 | F32: c-tex_0 | H32: a-tex_0 | AA32: MAACT3 | AB32: a-tex_0 | AD32: a-tex_i | AE32: a-tex_i | AJ32: oil | AK32: a-petr-0 | AM32: oil | AN32: c-petr-0 | AS32: a-tex_0 | AT32: c-tex_0
A33: a-wap_0 | C33: a-wap_i | D33: a-wap_0 | F33: c-wap_0 | H33: a-wap_0 | AA33: MAACT3 | AB33: a-wap_0 | AD33: a-wap_i | AE33: a-wap_i | AJ33: oil | AK33: a-auxp-0 | AM33: oil | AN33: c-auxp-0 | AS33: a-wap_0 | AT33: c-wap_0
A34: a-lea_0 | C34: a-lea_i | D34: a-lea_0 | F34: c-lea_0 | H34: a-lea_0 | AA34: MAACT3 | AB34: a-lea_0 | AD34: a-lea_i | AE34: a-lea_i | AJ34: gas | AK34: a-petr-0 | AM34: gas | AN34: c-petr-0 | AS34: a-lea_0 | AT34: c-lea_0
A35: a-lum_0 | C35: a-lum_i | D35: a-lum_0 | F35: c-lum_0 | H35: a-lum_0 | AA35: MAACT3 | AB35: a-lum_0 | AD35: a-lum_i | AE35: a-lum_i | AJ35: gas | AK35: a-auxp-0 | AM35: gas | AN35: c-auxp-0 | AS35: a-lum_0 | AT35: c-lum_0
A36: a-ppp_0 | C36: a-ppp_i | D36: a-ppp_0 | F36: c-ppp_0 | H36: a-ppp_0 | AA36: MAACT3 | AB36: a-ppp_0 | AD36: a-ppp_i | AE36: a-ppp_i | AJ36: oxt | AK36: a-mmet-0 | AM36: oxt | AN36: c-mmet-0 | AS36: a-ppp_0 | AT36: c-ppp_0
A37: a-p_c_0 | C37: a-p_c_i | D37: a-p_c_0 | F37: c-p_c_0 | H37: a-p_c_0 | AA37: MAACT3 | AB37: a-p_c_0 | AD37: a-p_c_i | AE37: a-p_c_i | AJ37: cmt | AK37: a-pmea-0 | AM37: cmt | AN37: c-pmea-0 | AS37: a-p_c_0 | AT37: c-p_c_0
A38: a-chm_0 | C38: a-chm_i | D38: a-chm_0 | F38: c-chm_0 | H38: a-chm_0 | AA38: MAACT3 | AB38: a-chm_0 | AD38: a-chm_i | AE38: a-chm_i | AJ38: omt | AK38: a-pmea-0 | AM38: omt | AN38: c-pmea-0 | AS38: a-chm_0 | AT38: c-chm_0
A39: a-bph_0 | C39: a-bph_i | D39: a-bph_0 | F39: c-bph_0 | H39: a-bph_0 | AA39: MAACT3 | AB39: a-bph_0 | AD39: a-bph_i | AE39: a-bph_i | AJ39: vol | AK39: a-eoil-0 | AM39: vol | AN39: c-eoil-0 | AS39: a-bph_0 | AT39: c-bph_0
A40: a-rpp_0 | C40: a-rpp_i | D40: a-rpp_0 | F40: c-rpp_0 | H40: a-rpp_0 | AA40: MAACT3 | AB40: a-rpp_0 | AD40: a-rpp_i | AE40: a-rpp_i | AJ40: mil | AK40: a-edai-0 | AM40: mil | AN40: c-edai-0 | AS40: a-rpp_0 | AT40: c-rpp_0
...

Sheet Macro
A1: Macro control totals
A3: Potential macro controls
A4: GAMS Name | C4: Description
A5: macro | B5: macroMat
A6: tfidemand2 | C6: Total fixed i-INVestment demand
A7: tgdpfc2 | C7: Total GDP at factor cost
A8: tgdpmp2 | C8: Total GDP at market prices
A9: tgosyrow2 | C9: Total GOS income from RoW
A10: tlabyrow2 | C10: Total labour income from RoW
A11: teyfact2 | C11: Total enterprise income from factors
A12: teygov2 | C12: Total enterprise income from government
A13: tcomtax2 | C13: Total commmodity taxes
A14: texctax2 | C14: Total excise tax revenues
A15: tacttax2 | C15: Total activity taxes and subsdies
A16: tindtax2 | C16: Total activity taxes
A17: tdetax2 | C17: Total enterprise income taxes
... A21: tnetfacrow2 | C21: Total net factor income from RoW

Sheet MACRO-Sam
A1: macscale | B1: 0

Sheet Proto-SAM

Sheet Fixes
